Workbook

Sheet 1월_정산내역서
A1: 네이버 프렌즈 어드민 > Comic > [시리즈] 매출 통계(이용권 포함) > [CP용] 정산내역서 > 내역 확인 후 세금계산서 정발행
A3: 구분 | B3: 매출액 | C3: 대손수수료 | D3: 결제수수료 | E3: 순매출액 | F3: CP 공급가액 | G3: CP 부가세액 | H3: CP 정산액 | I3: WEBTOON 수익
A4: 유상이용권-IAB NPAY | B4: 215911800 | C4: 0 | D4: 19432062 | E4: 196479738 | F4: 117887843 | G4: 0 | H4: 117887843 | I4: 78591895
A5: 유상금액보정 | B5: 3865 | C5: 0 | D5: 0 | E5: 3865 | F5: 2319 | G5: 0 | H5: 2319 | I5: 1546
A6: 유상이용권-IAB | B6: 153323574 | C6: 0 | D6: 15332357 | E6: 137991217 | F6: 82794730 | G6: 0 | H6: 82794730 | I6: 55196487
A7: 유상이용권-IAP | B7: 241890978 | C7: 0 | D7: 72567293 | E7: 169323685 | F7: 101594211 | G7: 0 | H7: 101594211 | I7: 67729474
A8: 유상이용권-원스토어 | B8: 3840960 | C8: 0 | D8: 307277 | E8: 3533683 | F8: 2120210 | G8: 0 | H8: 2120210 | I8: 1413473
A9: 무상이용권 | B9: 206814125 | C9: 0 | D9: 0 | E9: 206814125 | F9: 124088475 | G9: 0 | H9: 124088475 | I9: 82725650
A10: 유상이용권-리딤 | B10: 1251500 | C10: 0 | D10: 187725 | E10: 1063775 | F10: 638265 | G10: 0 | H10: 638265 | I10: 425510
A11: 유상이용권-웹+자동충전 | B11: 278145515 | C11: 0 | D11: 8344365 | E11: 269801150 | F11: 161880690 | G11: 0 | H11: 161880690 | I11: 107920460
A12: 합계 | B12: 1101182317 | C12: 0 | D12: 116171079 | E12: 985011238 | F12: 591006743 | G12: 0 | H12: 591006743 | I12: 394004495
A14: 구분 | B14: 매출액 | C14: 대손수수료 | D14: 결제수수료 | E14: 순매출액 | F14: CP 공급가액 | G14: CP 부가세액 | H14: CP 정산액 | I14: WEBTOON 수익
A15: 유상이용권-리딤 | B15: 5900 | C15: 0 | D15: 885 | E15: 5015 | F15: 3009 | G15: 0 | H15: 3009 | I15: 2006
A16: 유상금액보정 | B16: 416 | C16: 0 | D16: 0 | E16: 416 | F16: 250 | G16: 0 | H16: 250 | I16: 166
A17: 무상이용권 | B17: 937745 | C17: 0 | D17: 0 | E17: 937745 | F17: 562647 | G17: 0 | H17: 562647 | I17: 375098
A18: 유상이용권-IAB | B18: 173471 | C18: 0 | D18: 17347 | E18: 156124 | F18: 93674 | G18: 0 | H18: 93674 | I18: 62450
A19: 유상이용권-IAP | B19: 229329 | C19: 0 | D19: 68799 | E19: 160530 | F19: 96318 | G19: 0 | H19: 96318 | I19: 64212
A20: 유상이용권-IAB NPAY | B20: 265440 | C20: 0 | D20: 23890 | E20: 241550 | F20: 144930 | G20: 0 | H20: 144930 | I20: 96620
A21: 유상이용권-웹+자동충전 | B21: 4149004 | C21: 0 | D21: 124470 | E21: 4024534 | F21: 2414720 | G21: 0 | H21: 2414720 | I21: 1609814
A22: 유상이용권-원스토어 | B22: 3360 | C22: 0 | D22: 269 | E22: 3091 | F22: 1855 | G22: 0 | H22: 1855 | I22: 1236
A23: 합계 | B23: 5764665 | C23: 0 | D23: 235660 | E23: 5529005 | F23: 3317403 | G23: 0 | H23: 3317403 | I23: 2211602
A26: 총 합계 | B26: =B12+B23 -> 1106946982 | C26: =C12+C23 -> 0 | D26: =D12+D23 -> 116406739 | E26: =E12+E23 -> 990540243 | F26: =F12+F23 -> 594324146 | G26: =G12+G23 -> 0 | H26: =H12+H23 -> 594324146 | I26: =I12+I23 -> 396216097
B28: =B26=SUMIFS('컨텐츠별 매출 통계'!CA:CA,'컨텐츠별 매출 통계'!CF:CF,"2026-01") -> TRUE | D28: =D26=SUMIFS('컨텐츠별 매출 통계'!$CB:$CB,'컨텐츠별 매출 통계'!$CF:$CF,"2026-01") -> TRUE | E28: =E26=SUMIFS('컨텐츠별 매출 통계'!$CC:$CC,'컨텐츠별 매출 통계'!$CF:$CF,"2026-01") -> TRUE | F28: =F26=SUMIFS('컨텐츠별 매출 통계'!$CN:$CN,'컨텐츠별 매출 통계'!$CF:$CF,"2026-01") -> TRUE | G28: =G26=SUMIFS('컨텐츠별 매출 통계'!$CO:$CO,'컨텐츠별 매출 통계'!$CF:$CF,"2026-01") -> TRUE | H28: =H26=SUMIFS('컨텐츠별 매출 통계'!$CP:$CP,'컨텐츠별 매출 통계'!$CF:$CF,"2026-01") -> TRUE

Sheet 1월_세금계산서
H26: 공급가액 | I26: 부가세 | J26: 합계
H27: 594324146 | I27: 0 | J27: 594324146
H28: =H27='1월_정산내역서'!F26 -> TRUE | I28: =I27='1월_정산내역서'!G26 -> TRUE | J28: =J27='1월_정산내역서'!H26 -> TRUE

Sheet 작품별 집계
A1: 네이버 프렌즈 어드민 > Comic > [시리즈] 매출 통계(이용권 포함) > [CP용] 컨텐츠별 매출 통계
CH2: =CD4-CI2 -> 0 | CI2: =SUM(CI7:CI98) -> 594324146 | CJ2: =CI2=CD4 -> TRUE
A3: 이용권 포함 컨텐츠별 매출 통계 | CB3: 0.6
BT4: =SUBTOTAL(109,BT5:BT99784) -> 282298800 | BU4: =SUBTOTAL(109,BU5:BU99784) -> 242120307 | BV4: =SUBTOTAL(109,BV5:BV99784) -> 153497045 | BW4: =SUBTOTAL(109,BW5:BW99784) -> 216177240 | BX4: =SUBTOTAL(109,BX5:BX99784) -> 3844320 | BY4: =SUBTOTAL(109,BY5:BY99784) -> 1257400 | BZ4: =SUBTOTAL(109,BZ5:BZ99784) -> 207751870 | CA4: =SUBTOTAL(109,CA5:CA99784) -> 9.9054024e+08 | ... CD4: =SUBTOTAL(109,CD5:CD99784) -> 594324146
A5: 컨텐츠 | B5: 컨텐츠No | C5: 공급자코드 | D5: CP명 | E5: 작가명 | F5: 출판사 | G5: 나이제한 | H5: 서비스일 | I5: 대여권 | R5: 소장권 | AA5: 쿠키로 대여 | AD5: 쿠키로 구매 | AG5: i쿠키로 대여 | AJ5: i쿠키로 구매 | AM5: 자동충전 쿠키로 대여 | AP5: 자동충전 쿠키로 구매 | AS5: 구글 쿠키로 대여 | AV5: 구글 쿠키로 구매 | AY5: 구글 외부 쿠키로 대여 | BB5: 구글 외부 쿠키로 구매 | BE5: 원스토어 쿠키로 대여 | BH5: 원스토어 쿠키로 구매 | BK5: 리딤 쿠키로 대여 | BN5: 리딤 쿠키로 구매 | BQ5: 유상 이용권 보정 | BR5: 마켓수수료(추정치) | BS5: 합계 | BT5: 유상 | BU5: 유상_iap | BV5: 유상_iab | BW5: 유상_iab(npay) | BX5: 유상_원스토어 | BY5: 유상_리딤 쿠키 | BZ5: 무상 | CA5: 정산기준 | CB5: 수익 | CC5: 조정 | CD5: 매출 확정
I6: 건수 | J6: 비정산 | K6: 무료이용권 | L6: 유상쿠키 | M6: 무상쿠키 | N6: 유상i쿠키 | O6: 무상i쿠키 | P6: 유상자동충전쿠키 | Q6: 무상자동충전쿠키 | R6: 건수 | S6: 비정산 | T6: 무료이용권 | U6: 유상쿠키 | V6: 무상쿠키 | W6: 유상i쿠키 | X6: 무상i쿠키 | Y6: 유상자동충전쿠키 | Z6: 무상자동충전쿠키 | AA6: 건수 | AB6: 유상 | AC6: 무상 | AD6: 건수 | AE6: 유상 | AF6: 무상 | AG6: 건수 | AH6: 유상 | AI6: 무상 | AJ6: 건수 | AK6: 유상 | AL6: 무상 | AM6: 건수 | AN6: 유상 | AO6: 무상 | AP6: 건수 | AQ6: 유상 | AR6: 무상 | AS6: 건수 | AT6: 유상 | AU6: 무상 | AV6: 건수 | AW6: 유상 | AX6: 무상 | AY6: 건수 | AZ6: 유상 | BA6: 무상 | BB6: 건수 | BC6: 유상 | BD6: 무상 | BE6: 건수 | BF6: 유상 | BG6: 무상 | BH6: 건수 | BI6: 유상 | BJ6: 무상 | BK6: 건수 | BL6: 유상 | BM6: 무상 | BN6: 건수 | BO6: 유상 | BP6: 무상
A7: 캐슬2:만인지상 | B7: 499884 | D7: 더그림엔터테인먼트_브랜드 | E7: 정연 | F7: 정연 | G7: 15세 이상 이용가능 | H7: 2026.01.28 | I7: 0 | J7: 0 | K7: 0 | L7: 0 | M7: 0 | N7: 0 | O7: 0 | P7: 0 | Q7: 0 | R7: 0 | S7: 0 | T7: 0 | U7: 0 | V7: 0 | W7: 0 | X7: 0 | Y7: 0 | Z7: 0 | AA7: 306206 | AB7: 32163360 | AC7: 25449894 | AD7: 17047 | AE7: 3465140 | AF7: 3177395 | AG7: 211021 | AH7: 43733023 | AI7: 5223700 | AJ7: 4753 | AK7: 1800199 | AL7: 376800 | AM7: 39091 | AN7: 7579100 | AO7: 194500 | AP7: 3431 | AQ7: 1346600 | AR7: 31200 | AS7: 78486 | AT7: 18411317 | AU7: 51400 | AV7: 3563 | AW7: 1776494 | AX7: 5900 | AY7: 124294 | AZ7: 29284680 | BA7: 73800 | BB7: 4917 | BC7: 2361600 | BD7: 10000 | BE7: 372 | BF7: 87720 | BG7: 200 | BH7: 52 | BI7: 23040 | BJ7: 0 | BK7: 416 | BL7: 81800 | BM7: 0 | BN7: 61 | BO7: 23900 | BP7: 0 | BQ7: 601 | BR7: 19888237 | BS7: 176732762 | BT7: =L7+U7+AB7+AE7+AN7+AQ7 -> 44554200 | BU7: =AH7+AK7 -> 45533222 | BV7: =AT7+AW7 -> 20187811 | BW7: =+AZ7+BC7 -> 31646280 | BX7: =BF7+BI7 -> 110760 | BY7: =+BL7+BO7 -> 105700 | BZ7: =M7+AC7+AF7+AI7+AL7+AO7+AR7+K7+AU7+AX7+BA7+BD7+BG7+BJ7+BM7+BP7 -> 34594789 | CA7: =IF((BT7+BU7+BZ7+BV7+BW7+BX7+BY7)=BS7,BS7-BR7,"?""") -> 1.5684453e+08 | CB7: =ROUND(CA7*$CB$3,) -> 94106715 | CC7: -1 | CD7: =CB7+CC7 -> 94106714 | CE7: =A7 -> 캐슬2:만인지상 | CF7: =SUBSTITUTE(CE7," ","") -> 캐슬2:만인지상 | CG7: =CE7=CF7 -> TRUE | CH7: =CF7 -> 캐슬2:만인지상 | CI7: =IFERROR(_xlfn.XLOOKUP(CH7,$CF$5:$CF$60,$CD$5:$CD$60),"") -> 94106714 | CJ7: MG | CK7: =SUMIFS('컨텐츠별 매출 통계'!CV:CV,'컨텐츠별 매출 통계'!A:A,'작품별 집계'!A7,'컨텐츠별 매출 통계'!CF:CF,"2026-01") -> 94106714 | CL7: =CD7-CK7 -> 0
A8: 개짓 | B8: 591197 | D8: 더그림엔터테인먼트_브랜드 | E8: 서인화, MUTE | F8: MUTE | G8: 19세 이상 이용가능 | H8: 2026.01.31 | I8: 0 | J8: 0 | K8: 0 | L8: 0 | M8: 0 | N8: 0 | O8: 0 | P8: 0 | Q8: 0 | R8: 0 | S8: 0 | T8: 0 | U8: 0 | V8: 0 | W8: 0 | X8: 0 | Y8: 0 | Z8: 0 | AA8: 194957 | AB8: 22728720 | AC8: 32372151 | AD8: 9185 | AE8: 1544500 | AF8: 2824340 | AG8: 102128 | AH8: 24081739 | AI8: 9995000 | AJ8: 2820 | AK8: 822738 | AL8: 681400 | AM8: 12552 | AN8: 3639300 | AO8: 79000 | AP8: 1463 | AQ8: 687600 | AR8: 24400 | AS8: 25467 | AT8: 8949288 | AU8: 12300 | AV8: 981 | AW8: 577633 | AX8: 3300 | AY8: 69158 | AZ8: 24264600 | BA8: 45200 | BB8: 2339 | BC8: 1368600 | BD8: 7400 | BE8: 3655 | BF8: 1276080 | BG8: 3400 | BH8: 1006 | BI8: 579600 | BJ8: 3900 | BK8: 525 | BL8: 154000 | BM8: 0 | BN8: 38 | BO8: 16800 | BP8: 0 | BQ8: 48 | BR8: 11763100 | BS8: 136742989 | BT8: =L8+U8+AB8+AE8+AN8+AQ8 -> 28600120 | BU8: =AH8+AK8 -> 24904477 | BV8: =AT8+AW8 -> 9526921 | BW8: =+AZ8+BC8 -> 25633200 | BX8: =BF8+BI8 -> 1855680 | BY8: =+BL8+BO8 -> 170800 | BZ8: =M8+AC8+AF8+AI8+AL8+AO8+AR8+K8+AU8+AX8+BA8+BD8+BG8+BJ8+BM8+BP8 -> 46051791 | CA8: =IF((BT8+BU8+BZ8+BV8+BW8+BX8+BY8)=BS8,BS8-BR8,"?""") -> 1.2497989e+08 | CB8: =ROUND(CA8*$CB$3,) -> 74987934 | CC8: -1 | CD8: =CB8+CC8 -> 74987933 | CE8: =A8 -> 개짓 | CF8: =SUBSTITUTE(CE8," ","") -> 개짓 | CG8: =CE8=CF8 -> TRUE | CH8: =CF8 -> 개짓 | CI8: =IFERROR(_xlfn.XLOOKUP(CH8,$CF$5:$CF$60,$CD$5:$CD$60),"") -> 74987933 | CJ8: MG | CK8: =SUMIFS('컨텐츠별 매출 통계'!CV:CV,'컨텐츠별 매출 통계'!A:A,'작품별 집계'!A8,'컨텐츠별 매출 통계'!CF:CF,"2026-01") -> 74987933 | CL8: =CD8-CK8 -> 0
A9: 김부장 | B9: 450111 | D9: 더그림엔터테인먼트_브랜드 | E9: 정종택 | F9: 박만사 | G9: 15세 이상 이용가능 | H9: 2026.01.26 | I9: 0 | J9: 0 | K9: 0 | L9: 0 | M9: 0 | N9: 0 | O9: 0 | P9: 0 | Q9: 0 | R9: 0 | S9: 0 | T9: 0 | U9: 0 | V9: 0 | W9: 0 | X9: 0 | Y9: 0 | Z9: 0 | AA9: 145624 | AB9: 26786900 | AC9: 14597645 | AD9: 1163 | AE9: 404700 | AF9: 222595 | AG9: 99665 | AH9: 32538269 | AI9: 2524900 | AJ9: 264 | AK9: 134870 | AL9: 17500 | AM9: 28457 | AN9: 8306200 | AO9: 184900 | AP9: 454 | AQ9: 225300 | AR9: 8000 | AS9: 66618 | AT9: 23429770 | AU9: 66400 | AV9: 402 | AW9: 245363 | AX9: 100 | AY9: 68566 | AZ9: 24232560 | BA9: 69300 | BB9: 416 | BC9: 253320 | BD9: 1400 | BE9: 283 | BF9: 97800 | BG9: 600 | BH9: 28 | BI9: 15960 | BJ9: 500 | BK9: 408 | BL9: 119300 | BM9: 0 | BN9: 5 | BO9: 2200 | BP9: 0 | BQ9: 423 | BR9: 15472190 | BS9: 134486352 | BT9: =L9+U9+AB9+AE9+AN9+AQ9 -> 35723100 | BU9: =AH9+AK9 -> 32673139 | BV9: =AT9+AW9 -> 23675133 | BW9: =+AZ9+BC9 -> 24485880 | BX9: =BF9+BI9 -> 113760 | BY9: =+BL9+BO9 -> 121500 | BZ9: =M9+AC9+AF9+AI9+AL9+AO9+AR9+K9+AU9+AX9+BA9+BD9+BG9+BJ9+BM9+BP9 -> 17693840 | CA9: =IF((BT9+BU9+BZ9+BV9+BW9+BX9+BY9)=BS9,BS9-BR9,"?""") -> 1.1901416e+08 | CB9: =ROUND(CA9*$CB$3,) -> 71408497 | CD9: =CB9+CC9 -> 71408497 | CE9: =A9 -> 김부장 | CF9: =SUBSTITUTE(CE9," ","") -> 김부장 | CG9: =CE9=CF9 -> TRUE | CH9: =CF9 -> 김부장 | CI9: =IFERROR(_xlfn.XLOOKUP(CH9,$CF$5:$CF$60,$CD$5:$CD$60),"") -> 71408497 | CJ9: MG | CK9: =SUMIFS('컨텐츠별 매출 통계'!CV:CV,'컨텐츠별 매출 통계'!A:A,'작품별 집계'!A9,'컨텐츠별 매출 통계'!CF:CF,"2026-01") -> 71408497 | CL9: =CD9-CK9 -> 0
A10: 밤친구 | B10: 666996 | D10: 더그림엔터테인먼트_브랜드 | E10: MUTE | F10: MUTE | G10: 19세 이상 이용가능 | H10: 2026.01.29 | I10: 15 | J10: 848574 | K10: 4500 | L10: 0 | M10: 0 | N10: 0 | O10: 0 | P10: 0 | Q10: 0 | R10: 0 | S10: 0 | T10: 0 | U10: 0 | V10: 0 | W10: 0 | X10: 0 | Y10: 0 | Z10: 0 | AA10: 140378 | AB10: 15196760 | AC10: 24742409 | AD10: 2176 | AE10: 469000 | AF10: 595295 | AG10: 73479 | AH10: 18403607 | AI10: 6468700 | AJ10: 702 | AK10: 299995 | AL10: 93200 | AM10: 11663 | AN10: 3394000 | AO10: 70800 | AP10: 627 | AQ10: 308400 | AR10: 9400 | AS10: 27788 | AT10: 9821041 | AU10: 33800 | AV10: 418 | AW10: 245155 | AX10: 3000 | AY10: 81356 | AZ10: 28702560 | BA10: 104500 | BB10: 901 | BC10: 536040 | BD10: 4600 | BE10: 2612 | BF10: 912360 | BG10: 4300 | BH10: 517 | BI10: 302400 | BJ10: 1700 | BK10: 489 | BL10: 143100 | BM10: 0 | BN10: 5 | BO10: 2000 | BP10: 0 | BQ10: 129 | BR10: 9949160.9 | BS10: 110872622 | BT10: =L10+U10+AB10+AE10+AN10+AQ10 -> 19368160 | BU10: =AH10+AK10 -> 18703602 | BV10: =AT10+AW10 -> 10066196 | BW10: =+AZ10+BC10 -> 29238600 | BX10: =BF10+BI10 -> 1214760 | BY10: =+BL10+BO10 -> 145100 | BZ10: =M10+AC10+AF10+AI10+AL10+AO10+AR10+K10+AU10+AX10+BA10+BD10+BG10+BJ10+BM10+BP10 -> 32136204 | CA10: =IF((BT10+BU10+BZ10+BV10+BW10+BX10+BY10)=BS10,BS10-BR10,"?""") -> 1.0092346e+08 | CB10: =ROUND(CA10*$CB$3,) -> 60554077 | CD10: =CB10+CC10 -> 60554077 | CE10: =A10 -> 밤친구 | CF10: =SUBSTITUTE(CE10," ","") -> 밤친구 | CG10: =CE10=CF10 -> TRUE | CH10: =CF10 -> 밤친구 | CI10: =IFERROR(_xlfn.XLOOKUP(CH10,$CF$5:$CF$60,$CD$5:$CD$60),"") -> 60554077 | CJ10: MG | CK10: =SUMIFS('컨텐츠별 매출 통계'!CV:CV,'컨텐츠별 매출 통계'!A:A,'작품별 집계'!A10,'컨텐츠별 매출 통계'!CF:CF,"2026-01") -> 60554077 | CL10: =CD10-CK10 -> 0
A11: 왕따가 격투기를 너무 잘함 | B11: 499170 | D11: 더그림엔터테인먼트_브랜드 | E11: 김꿀빨 | F11: 박만사 | G11: 15세 이상 이용가능 | H11: 2026.01.27 | I11: 0 | J11: 0 | K11: 0 | L11: 0 | M11: 0 | N11: 0 | O11: 0 | P11: 0 | Q11: 0 | R11: 0 | S11: 0 | T11: 0 | U11: 0 | V11: 0 | W11: 0 | X11: 0 | Y11: 0 | Z11: 0 | AA11: 93908 | AB11: 17883900 | AC11: 8896936 | AD11: 821 | AE11: 199400 | AF11: 124160 | AG11: 53601 | AH11: 17490967 | AI11: 1372600 | AJ11: 102 | AK11: 39469 | AL11: 7900 | AM11: 28033 | AN11: 8159800 | AO11: 199900 | AP11: 472 | AQ11: 196100 | AR11: 7200 | AS11: 36030 | AT11: 12722505 | AU11: 39900 | AV11: 174 | AW11: 86852 | AX11: 1000 | AY11: 41653 | AZ11: 14752200 | BA11: 42400 | BB11: 185 | BC11: 90240 | BD11: 0 | BE11: 114 | BF11: 40080 | BG11: 0 | BH11: 3 | BI11: 1440 | BJ11: 0 | BK11: 140 | BL11: 40800 | BM11: 0 | BN11: 1 | BO11: 400 | BP11: 0 | BQ11: 257 | BR11: 8678556 | BS11: 82396149 | BT11: =L11+U11+AB11+AE11+AN11+AQ11 -> 26439200 | BU11: =AH11+AK11 -> 17530436 | BV11: =AT11+AW11 -> 12809357 | BW11: =+AZ11+BC11 -> 14842440 | BX11: =BF11+BI11 -> 41520 | BY11: =+BL11+BO11 -> 41200 | BZ11: =M11+AC11+AF11+AI11+AL11+AO11+AR11+K11+AU11+AX11+BA11+BD11+BG11+BJ11+BM11+BP11 -> 10691996 | CA11: =IF((BT11+BU11+BZ11+BV11+BW11+BX11+BY11)=BS11,BS11-BR11,"?""") -> 73717593 | CB11: =ROUND(CA11*$CB$3,) -> 44230556 | CD11: =CB11+CC11 -> 44230556 | CE11: =A11 -> 왕따가 격투기를 너무 잘함 | CF11: =SUBSTITUTE(CE11," ","") -> 왕따가격투기를너무잘함 | CG11: =CE11=CF11 -> FALSE | CH11: =CF11 -> 왕따가격투기를너무잘함 | CI11: =IFERROR(_xlfn.XLOOKUP(CH11,$CF$5:$CF$60,$CD$5:$CD$60),"") -> 44230556 | CJ11: MG | CK11: =SUMIFS('컨텐츠별 매출 통계'!CV:CV,'컨텐츠별 매출 통계'!A:A,'작품별 집계'!A11,'컨텐츠별 매출 통계'!CF:CF,"2026-01") -> 44230556 | CL11: =CD11-CK11 -> 0
A12: 태존비록 | B12: 645729 | D12: 더그림엔터테인먼트_브랜드 | E12: 레드훅 | F12: 비가, 김꿀빨 / 레드훅 | G12: 15세 이상 이용가능 | H12: 2026.01.31 | I12: 0 | J12: 0 | K12: 0 | L12: 0 | M12: 0 | N12: 0 | O12: 0 | P12: 0 | Q12: 0 | R12: 0 | S12: 0 | T12: 0 | U12: 0 | V12: 0 | W12: 0 | X12: 0 | Y12: 0 | Z12: 0 | AA12: 78192 | AB12: 15758440 | AC12: 6915430 | AD12: 1174 | AE12: 349100 | AF12: 134025 | AG12: 36549 | AH12: 11729084 | AI12: 1149000 | AJ12: 180 | AK12: 67372 | AL12: 15400 | AM12: 28242 | AN12: 8242000 | AO12: 193300 | AP12: 752 | AQ12: 326600 | AR12: 9000 | AS12: 34524 | AT12: 12237208 | AU12: 39900 | AV12: 238 | AW12: 135936 | AX12: 0 | AY12: 43550 | AZ12: 15514200 | BA12: 38500 | BB12: 295 | BC12: 153360 | BD12: 400 | BE12: 174 | BF12: 62040 | BG12: 0 | BH12: 16 | BI12: 7680 | BJ12: 0 | BK12: 223 | BL12: 65900 | BM12: 0 | BN12: 6 | BO12: 2200 | BP12: 0 | BQ12: 36 | BR12: 6942407.3 | BS12: 73146075 | BT12: =L12+U12+AB12+AE12+AN12+AQ12 -> 24676140 | BU12: =AH12+AK12 -> 11796456 | BV12: =AT12+AW12 -> 12373144 | BW12: =+AZ12+BC12 -> 15667560 | BX12: =BF12+BI12 -> 69720 | BY12: =+BL12+BO12 -> 68100 | BZ12: =M12+AC12+AF12+AI12+AL12+AO12+AR12+K12+AU12+AX12+BA12+BD12+BG12+BJ12+BM12+BP12 -> 8494955 | CA12: =IF((BT12+BU12+BZ12+BV12+BW12+BX12+BY12)=BS12,BS12-BR12,"?""") -> 66203668 | CB12: =ROUND(CA12*$CB$3,) -> 39722201 | CD12: =CB12+CC12 -> 39722201 | CE12: =A12 -> 태존비록 | CF12: =SUBSTITUTE(CE12," ","") -> 태존비록 | CG12: =CE12=CF12 -> TRUE | CH12: =CF12 -> 태존비록 | CI12: =IFERROR(_xlfn.XLOOKUP(CH12,$CF$5:$CF$60,$CD$5:$CD$60),"") -> 39722201 | CJ12: MG | CK12: =SUMIFS('컨텐츠별 매출 통계'!CV:CV,'컨텐츠별 매출 통계'!A:A,'작품별 집계'!A12,'컨텐츠별 매출 통계'!CF:CF,"2026-01") -> 39722201 | CL12: =CD12-CK12 -> 0
A13: 오! 나의 교주님 | B13: 656399 | D13: 더그림엔터테인먼트_브랜드 | E13: 김꿀빨, 김완두 | F13: 김꿀빨, 김완두 | G13: 19세 이상 이용가능 | H13: 2026.01.29 | I13: 0 | J13: 0 | K13: 0 | L13: 0 | M13: 0 | N13: 0 | O13: 0 | P13: 0 | Q13: 0 | R13: 0 | S13: 0 | T13: 0 | U13: 0 | V13: 0 | W13: 0 | X13: 0 | Y13: 0 | Z13: 0 | AA13: 128253 | AB13: 12331700 | AC13: 12011989 | AD13: 224 | AE13: 31400 | AF13: 38055 | AG13: 93878 | AH13: 17745372 | AI13: 3896800 | AJ13: 25 | AK13: 3600 | AL13: 4000 | AM13: 15373 | AN13: 2988800 | AO13: 73500 | AP13: 96 | AQ13: 30300 | AR13: 600 | AS13: 28018 | AT13: 6618057 | AU13: 20300 | AV13: 55 | AW13: 22360 | AX13: 200 | AY13: 46286 | AZ13: 10959600 | BA13: 31400 | BB13: 80 | BC13: 47880 | BD13: 300 | BE13: 94 | BF13: 21960 | BG13: 0 | BH13: 1 | BI13: 1080 | BJ13: 0 | BK13: 282 | BL13: 56200 | BM13: 0 | BN13: 0 | BO13: 0 | BP13: 0 | BQ13: 102 | BR13: 7451142.6 | BS13: 66935453 | BT13: =L13+U13+AB13+AE13+AN13+AQ13 -> 15382200 | BU13: =AH13+AK13 -> 17748972 | BV13: =AT13+AW13 -> 6640417 | BW13: =+AZ13+BC13 -> 11007480 | BX13: =BF13+BI13 -> 23040 | BY13: =+BL13+BO13 -> 56200 | BZ13: =M13+AC13+AF13+AI13+AL13+AO13+AR13+K13+AU13+AX13+BA13+BD13+BG13+BJ13+BM13+BP13 -> 16077144 | CA13: =IF((BT13+BU13+BZ13+BV13+BW13+BX13+BY13)=BS13,BS13-BR13,"?""") -> 59484310 | CB13: =ROUND(CA13*$CB$3,) -> 35690586 | CD13: =CB13+CC13 -> 35690586 | CE13: =A13 -> 오! 나의 교주님 | CF13: =SUBSTITUTE(CE13," ","") -> 오!나의교주님 | CG13: =CE13=CF13 -> FALSE | CH13: =CF13 -> 오!나의교주님 | CI13: =IFERROR(_xlfn.XLOOKUP(CH13,$CF$5:$CF$60,$CD$5:$CD$60),"") -> 35690586 | CJ13: MG | CK13: =SUMIFS('컨텐츠별 매출 통계'!CV:CV,'컨텐츠별 매출 통계'!A:A,'작품별 집계'!A13,'컨텐츠별 매출 통계'!CF:CF,"2026-01") -> 35690586 | CL13: =CD13-CK13 -> 0
A14: 데이워커 | B14: 577640 | D14: 더그림엔터테인먼트_브랜드 | E14: MUTE | F14: MUTE | G14: 19세 이상 이용가능 | H14: 2026.01.30 | I14: 0 | J14: 0 | K14: 0 | L14: 0 | M14: 0 | N14: 0 | O14: 0 | P14: 0 | Q14: 0 | R14: 0 | S14: 0 | T14: 0 | U14: 0 | V14: 0 | W14: 0 | X14: 0 | Y14: 0 | Z14: 0 | AA14: 55638 | AB14: 10993380 | AC14: 5050066 | AD14: 720 | AE14: 307800 | AF14: 107380 | AG14: 45208 | AH14: 14913885 | AI14: 1084800 | AJ14: 55 | AK14: 27600 | AL14: 5000 | AM14: 14217 | AN14: 4153400 | AO14: 96000 | AP14: 200 | AQ14: 165300 | AR14: 9800 | AS14: 34229 | AT14: 12088192 | AU14: 35600 | AV14: 329 | AW14: 282182 | AX14: 800 | AY14: 32853 | AZ14: 11678400 | BA14: 32300 | BB14: 186 | BC14: 138720 | BD14: 0 | BE14: 40 | BF14: 14400 | BG14: 0 | BH14: 3 | BI14: 1800 | BJ14: 0 | BK14: 117 | BL14: 34800 | BM14: 0 | BN14: 1 | BO14: 500 | BP14: 0 | BQ14: 63 | BR14: 7258209.2 | BS14: 61222105 | BT14: =L14+U14+AB14+AE14+AN14+AQ14 -> 15619880 | BU14: =AH14+AK14 -> 14941485 | BV14: =AT14+AW14 -> 12370374 | BW14: =+AZ14+BC14 -> 11817120 | BX14: =BF14+BI14 -> 16200 | BY14: =+BL14+BO14 -> 35300 | BZ14: =M14+AC14+AF14+AI14+AL14+AO14+AR14+K14+AU14+AX14+BA14+BD14+BG14+BJ14+BM14+BP14 -> 6421746 | CA14: =IF((BT14+BU14+BZ14+BV14+BW14+BX14+BY14)=BS14,BS14-BR14,"?""") -> 53963896 | CB14: =ROUND(CA14*$CB$3,) -> 32378337 | CC14: 1 | CD14: =CB14+CC14 -> 32378338 | CE14: =A14 -> 데이워커 | CF14: =SUBSTITUTE(CE14," ","") -> 데이워커 | CG14: =CE14=CF14 -> TRUE | CH14: =CF14 -> 데이워커 | CI14: =IFERROR(_xlfn.XLOOKUP(CH14,$CF$5:$CF$60,$CD$5:$CD$60),"") -> 32378338 | CJ14: MG | CK14: =SUMIFS('컨텐츠별 매출 통계'!CV:CV,'컨텐츠별 매출 통계'!A:A,'작품별 집계'!A14,'컨텐츠별 매출 통계'!CF:CF,"2026-01") -> 32378338 | CL14: =CD14-CK14 -> 0
A15: 백XX | B15: 493508 | D15: 더그림엔터테인먼트_브랜드 | E15: 펀치킥 | F15: 박만사 | G15: 15세 이상 이용가능 | H15: 2026.01.27 | I15: 0 | J15: 0 | K15: 0 | L15: 0 | M15: 0 | N15: 0 | O15: 0 | P15: 0 | Q15: 0 | R15: 0 | S15: 0 | T15: 0 | U15: 0 | V15: 0 | W15: 0 | X15: 0 | Y15: 0 | Z15: 0 | AA15: 63771 | AB15: 13204340 | AC15: 5154090 | AD15: 910 | AE15: 349400 | AF15: 117825 | AG15: 48205 | AH15: 15685739 | AI15: 1295800 | AJ15: 146 | AK15: 73800 | AL15: 10600 | AM15: 15198 | AN15: 4445700 | AO15: 93400 | AP15: 308 | AQ15: 161100 | AR15: 2300 | AS15: 23628 | AT15: 8350111 | AU15: 25500 | AV15: 175 | AW15: 109410 | AX15: 0 | AY15: 25508 | AZ15: 9054480 | BA15: 30500 | BB15: 177 | BC15: 118200 | BD15: 600 | BE15: 167 | BF15: 59160 | BG15: 0 | BH15: 8 | BI15: 4800 | BJ15: 0 | BK15: 134 | BL15: 39800 | BM15: 0 | BN15: 4 | BO15: 2000 | BP15: 0 | BQ15: 0 | BR15: 6955558 | BS15: 58388655 | BT15: =L15+U15+AB15+AE15+AN15+AQ15 -> 18160540 | BU15: =AH15+AK15 -> 15759539 | BV15: =AT15+AW15 -> 8459521 | BW15: =+AZ15+BC15 -> 9172680 | BX15: =BF15+BI15 -> 63960 | BY15: =+BL15+BO15 -> 41800 | BZ15: =M15+AC15+AF15+AI15+AL15+AO15+AR15+K15+AU15+AX15+BA15+BD15+BG15+BJ15+BM15+BP15 -> 6730615 | CA15: =IF((BT15+BU15+BZ15+BV15+BW15+BX15+BY15)=BS15,BS15-BR15,"?""") -> 51433097 | CB15: =ROUND(CA15*$CB$3,) -> 30859858 | CD15: =CB15+CC15 -> 30859858 | CE15: =A15 -> 백XX | CF15: =SUBSTITUTE(CE15," ","") -> 백XX | CG15: =CE15=CF15 -> TRUE | CH15: =CF15 -> 백XX | CI15: =IFERROR(_xlfn.XLOOKUP(CH15,$CF$5:$CF$60,$CD$5:$CD$60),"") -> 30859858 | CJ15: MG | CK15: =SUMIFS('컨텐츠별 매출 통계'!CV:CV,'컨텐츠별 매출 통계'!A:A,'작품별 집계'!A15,'컨텐츠별 매출 통계'!CF:CF,"2026-01") -> 30859858 | CL15: =CD15-CK15 -> 0
A16: 오늘도 퇴근 | B16: 662616 | D16: 더그림엔터테인먼트_브랜드 | E16: 물속 | F16: 파셔, 백초 / 물속 | G16: 12세 이상 이용가능 | H16: 2026.01.26 | I16: 0 | J16: 0 | K16: 0 | L16: 0 | M16: 0 | N16: 0 | O16: 0 | P16: 0 | Q16: 0 | R16: 0 | S16: 0 | T16: 0 | U16: 0 | V16: 0 | W16: 0 | X16: 0 | Y16: 0 | Z16: 0 | AA16: 32756 | AB16: 5956400 | AC16: 3471925 | AD16: 420 | AE16: 107400 | AF16: 69440 | AG16: 12345 | AH16: 3649448 | AI16: 641000 | AJ16: 68 | AK16: 26686 | AL16: 4000 | AM16: 10539 | AN16: 3072200 | AO16: 75700 | AP16: 222 | AQ16: 108700 | AR16: 1200 | AS16: 10383 | AT16: 3673220 | AU16: 13200 | AV16: 123 | AW16: 63460 | AX16: 0 | AY16: 16455 | AZ16: 5839920 | BA16: 23900 | BB16: 82 | BC16: 41160 | BD16: 0 | BE16: 84 | BF16: 29760 | BG16: 300 | BH16: 6 | BI16: 2880 | BJ16: 0 | BK16: 52 | BL16: 15300 | BM16: 0 | BN16: 0 | BO16: 0 | BP16: 0 | BQ16: 0 | BR16: 2288052.6 | BS16: 26887199 | BT16: =L16+U16+AB16+AE16+AN16+AQ16 -> 9244700 | BU16: =AH16+AK16 -> 3676134 | BV16: =AT16+AW16 -> 3736680 | BW16: =+AZ16+BC16 -> 5881080 | BX16: =BF16+BI16 -> 32640 | BY16: =+BL16+BO16 -> 15300 | BZ16: =M16+AC16+AF16+AI16+AL16+AO16+AR16+K16+AU16+AX16+BA16+BD16+BG16+BJ16+BM16+BP16 -> 4300665 | CA16: =IF((BT16+BU16+BZ16+BV16+BW16+BX16+BY16)=BS16,BS16-BR16,"?""") -> 24599146 | CB16: =ROUND(CA16*$CB$3,) -> 14759488 | CD16: =CB16+CC16 -> 14759488 | CE16: =A16 -> 오늘도 퇴근 | CF16: =SUBSTITUTE(CE16," ","") -> 오늘도퇴근 | CG16: =CE16=CF16 -> FALSE | CH16: =CF16 -> 오늘도퇴근 | CI16: =IFERROR(_xlfn.XLOOKUP(CH16,$CF$5:$CF$60,$CD$5:$CD$60),"") -> 14759488 | CJ16: MG | CK16: =SUMIFS('컨텐츠별 매출 통계'!CV:CV,'컨텐츠별 매출 통계'!A:A,'작품별 집계'!A16,'컨텐츠별 매출 통계'!CF:CF,"2026-01") -> 14759488 | CL16: =CD16-CK16 -> 0
A17: 구룡:사로카 | B17: 590132 | D17: 더그림엔터테인먼트_브랜드 | E17: 백인휘 | F17: 박만사 | G17: 15세 이상 이용가능 | H17: 2026.01.26 | I17: 0 | J17: 0 | K17: 0 | L17: 0 | M17: 0 | N17: 0 | O17: 0 | P17: 0 | Q17: 0 | R17: 0 | S17: 0 | T17: 0 | U17: 0 | V17: 0 | W17: 0 | X17: 0 | Y17: 0 | Z17: 0 | AA17: 28714 | AB17: 5383700 | AC17: 2834135 | AD17: 793 | AE17: 189000 | AF17: 120605 | AG17: 21825 | AH17: 7023718 | AI17: 653200 | AJ17: 174 | AK17: 58812 | AL17: 19400 | AM17: 4570 | AN17: 1339200 | AO17: 25300 | AP17: 196 | AQ17: 75400 | AR17: 4200 | AS17: 10277 | AT17: 3639751 | AU17: 8700 | AV17: 180 | AW17: 87104 | AX17: 800 | AY17: 14010 | AZ17: 4973640 | BA17: 13400 | BB17: 241 | BC17: 118080 | BD17: 0 | BE17: 70 | BF17: 25080 | BG17: 0 | BH17: 9 | BI17: 4320 | BJ17: 0 | BK17: 62 | BL17: 18500 | BM17: 0 | BN17: 6 | BO17: 2400 | BP17: 0 | BQ17: 244 | BR17: 3170798 | BS17: 26618445 | BT17: =L17+U17+AB17+AE17+AN17+AQ17 -> 6987300 | BU17: =AH17+AK17 -> 7082530 | BV17: =AT17+AW17 -> 3726855 | BW17: =+AZ17+BC17 -> 5091720 | BX17: =BF17+BI17 -> 29400 | BY17: =+BL17+BO17 -> 20900 | BZ17: =M17+AC17+AF17+AI17+AL17+AO17+AR17+K17+AU17+AX17+BA17+BD17+BG17+BJ17+BM17+BP17 -> 3679740 | CA17: =IF((BT17+BU17+BZ17+BV17+BW17+BX17+BY17)=BS17,BS17-BR17,"?""") -> 23447647 | CB17: =ROUND(CA17*$CB$3,) -> 14068588 | CD17: =CB17+CC17 -> 14068588 | CE17: =A17 -> 구룡:사로카 | CF17: =SUBSTITUTE(CE17," ","") -> 구룡:사로카 | CG17: =CE17=CF17 -> TRUE | CH17: =CF17 -> 구룡:사로카 | CI17: =IFERROR(_xlfn.XLOOKUP(CH17,$CF$5:$CF$60,$CD$5:$CD$60),"") -> 14068588 | CJ17: MG | CK17: =SUMIFS('컨텐츠별 매출 통계'!CV:CV,'컨텐츠별 매출 통계'!A:A,'작품별 집계'!A17,'컨텐츠별 매출 통계'!CF:CF,"2026-01") -> 14068588 | CL17: =CD17-CK17 -> 0
A18: 십이지소녀 | B18: 642001 | D18: 더그림엔터테인먼트_브랜드 | E18: 지지 | F18: MAJOR | G18: 15세 이상 이용가능 | H18: 2026.02.01 | I18: 0 | J18: 0 | K18: 0 | L18: 0 | M18: 0 | N18: 0 | O18: 0 | P18: 0 | Q18: 0 | R18: 0 | S18: 0 | T18: 0 | U18: 0 | V18: 0 | W18: 0 | X18: 0 | Y18: 0 | Z18: 0 | AA18: 21055 | AB18: 3869760 | AC18: 2191770 | AD18: 1263 | AE18: 361500 | AF18: 185115 | AG18: 12242 | AH18: 4039474 | AI18: 281400 | AJ18: 77 | AK18: 23520 | AL18: 9600 | AM18: 4419 | AN18: 1289500 | AO18: 30300 | AP18: 352 | AQ18: 147700 | AR18: 3800 | AS18: 17795 | AT18: 6224058 | AU18: 21000 | AV18: 533 | AW18: 274316 | AX18: 2700 | AY18: 8441 | AZ18: 2982000 | BA18: 12400 | BB18: 246 | BC18: 133440 | BD18: 300 | BE18: 20 | BF18: 7080 | BG18: 0 | BH18: 5 | BI18: 1920 | BJ18: 400 | BK18: 420 | BL18: 123900 | BM18: 0 | BN18: 30 | BO18: 11600 | BP18: 0 | BQ18: 0 | BR18: 2340224 | BS18: 22228553 | BT18: =L18+U18+AB18+AE18+AN18+AQ18 -> 5668460 | BU18: =AH18+AK18 -> 4062994 | BV18: =AT18+AW18 -> 6498374 | BW18: =+AZ18+BC18 -> 3115440 | BX18: =BF18+BI18 -> 9000 | BY18: =+BL18+BO18 -> 135500 | BZ18: =M18+AC18+AF18+AI18+AL18+AO18+AR18+K18+AU18+AX18+BA18+BD18+BG18+BJ18+BM18+BP18 -> 2738785 | CA18: =IF((BT18+BU18+BZ18+BV18+BW18+BX18+BY18)=BS18,BS18-BR18,"?""") -> 19888329 | CB18: =ROUND(CA18*$CB$3,) -> 11932997 | CD18: =CB18+CC18 -> 11932997 | CE18: =A18 -> 십이지소녀 | CF18: =SUBSTITUTE(CE18," ","") -> 십이지소녀 | CG18: =CE18=CF18 -> TRUE | CH18: =CF18 -> 십이지소녀 | CI18: =IFERROR(_xlfn.XLOOKUP(CH18,$CF$5:$CF$60,$CD$5:$CD$60),"") -> 11932997 | CJ18: MG | CK18: =SUMIFS('컨텐츠별 매출 통계'!CV:CV,'컨텐츠별 매출 통계'!A:A,'작품별 집계'!A18,'컨텐츠별 매출 통계'!CF:CF,"2026-01") -> 11932997 | CL18: =CD18-CK18 -> 0
A19: 밤의 방문자 | B19: 591459 | D19: 더그림엔터테인먼트_브랜드 | E19: MUTE | F19: MUTE | G19: 19세 이상 이용가능 | H19: 2025.11.26 | I19: 268 | J19: 394954 | K19: 80400 | L19: 0 | M19: 0 | N19: 0 | O19: 0 | P19: 0 | Q19: 0 | R19: 0 | S19: 0 | T19: 0 | U19: 0 | V19: 0 | W19: 0 | X19: 0 | Y19: 0 | Z19: 0 | AA19: 16420 | AB19: 2473200 | AC19: 2294910 | AD19: 189 | AE19: 64000 | AF19: 30315 | AG19: 11901 | AH19: 3709333 | AI19: 462700 | AJ19: 71 | AK19: 27720 | AL19: 11900 | AM19: 2462 | AN19: 719100 | AO19: 16300 | AP19: 97 | AQ19: 49800 | AR19: 2000 | AS19: 7712 | AT19: 2755179 | AU19: 7800 | AV19: 62 | AW19: 37200 | AX19: 0 | AY19: 18024 | AZ19: 6434040 | BA19: 16100 | BB19: 51 | BC19: 31200 | BD19: 0 | BE19: 324 | BF19: 115440 | BG19: 0 | BH19: 78 | BI19: 46080 | BJ19: 0 | BK19: 75 | BL19: 22500 | BM19: 0 | BN19: 1 | BO19: 500 | BP19: 0 | BQ19: 1767 | BR19: 2097727 | BS19: 19407717 | BT19: =L19+U19+AB19+AE19+AN19+AQ19 -> 3306100 | BU19: =AH19+AK19 -> 3737053 | BV19: =AT19+AW19 -> 2792379 | BW19: =+AZ19+BC19 -> 6465240 | BX19: =BF19+BI19 -> 161520 | BY19: =+BL19+BO19 -> 23000 | BZ19: =M19+AC19+AF19+AI19+AL19+AO19+AR19+K19+AU19+AX19+BA19+BD19+BG19+BJ19+BM19+BP19 -> 2922425 | CA19: =IF((BT19+BU19+BZ19+BV19+BW19+BX19+BY19)=BS19,BS19-BR19,"?""") -> 17309990 | CB19: =ROUND(CA19*$CB$3,) -> 10385994 | CD19: =CB19+CC19 -> 10385994 | CE19: =A19 -> 밤의 방문자 | CF19: =SUBSTITUTE(CE19," ","") -> 밤의방문자 | CG19: =CE19=CF19 -> FALSE | CH19: =CF19 -> 밤의방문자 | CI19: =IFERROR(_xlfn.XLOOKUP(CH19,$CF$5:$CF$60,$CD$5:$CD$60),"") -> 10385994 | CJ19: MG | CK19: =SUMIFS('컨텐츠별 매출 통계'!CV:CV,'컨텐츠별 매출 통계'!A:A,'작품별 집계'!A19,'컨텐츠별 매출 통계'!CF:CF,"2026-01") -> 10385994 | CL19: =CD19-CK19 -> 0
A20: 최악의 세대 | B20: 595746 | D20: 더그림엔터테인먼트_브랜드 | E20: 광산, MAJOR | F20: MAJOR | G20: 15세 이상 이용가능 | H20: 2026.02.01 | I20: 0 | J20: 0 | K20: 0 | L20: 0 | M20: 0 | N20: 0 | O20: 0 | P20: 0 | Q20: 0 | R20: 0 | S20: 0 | T20: 0 | U20: 0 | V20: 0 | W20: 0 | X20: 0 | Y20: 0 | Z20: 0 | AA20: 16980 | AB20: 3162720 | AC20: 1697215 | AD20: 189 | AE20: 50000 | AF20: 28500 | AG20: 11775 | AH20: 3775495 | AI20: 368900 | AJ20: 46 | AK20: 15348 | AL20: 5300 | AM20: 3978 | AN20: 1165600 | AO20: 22700 | AP20: 72 | AQ20: 27900 | AR20: 900 | AS20: 5831 | AT20: 2062559 | AU20: 5600 | AV20: 54 | AW20: 25532 | AX20: 0 | AY20: 8564 | AZ20: 3045120 | BA20: 6700 | BB20: 47 | BC20: 22800 | BD20: 0 | BE20: 22 | BF20: 7920 | BG20: 0 | BH20: 0 | BI20: 0 | BJ20: 0 | BK20: 16 | BL20: 4800 | BM20: 0 | BN20: 0 | BO20: 0 | BP20: 0 | BQ20: 0 | BR20: 1755715 | BS20: 15501609 | BT20: =L20+U20+AB20+AE20+AN20+AQ20 -> 4406220 | BU20: =AH20+AK20 -> 3790843 | BV20: =AT20+AW20 -> 2088091 | BW20: =+AZ20+BC20 -> 3067920 | BX20: =BF20+BI20 -> 7920 | BY20: =+BL20+BO20 -> 4800 | BZ20: =M20+AC20+AF20+AI20+AL20+AO20+AR20+K20+AU20+AX20+BA20+BD20+BG20+BJ20+BM20+BP20 -> 2135815 | CA20: =IF((BT20+BU20+BZ20+BV20+BW20+BX20+BY20)=BS20,BS20-BR20,"?""") -> 13745894 | CB20: =ROUND(CA20*$CB$3,) -> 8247536 | CD20: =CB20+CC20 -> 8247536 | CE20: =A20 -> 최악의 세대 | CF20: =SUBSTITUTE(CE20," ","") -> 최악의세대 | CG20: =CE20=CF20 -> FALSE | CH20: =CF20 -> 최악의세대 | CI20: =IFERROR(_xlfn.XLOOKUP(CH20,$CF$5:$CF$60,$CD$5:$CD$60),"") -> 8247536 | CJ20: MG | CK20: =SUMIFS('컨텐츠별 매출 통계'!CV:CV,'컨텐츠별 매출 통계'!A:A,'작품별 집계'!A20,'컨텐츠별 매출 통계'!CF:CF,"2026-01") -> 8247536 | CL20: =CD20-CK20 -> 0
A21: 남제 | B21: 598352 | D21: 더그림엔터테인먼트_브랜드 | E21: 윤영일 | F21: MAJOR | G21: 15세 이상 이용가능 | H21: 2026.01.27 | I21: 0 | J21: 0 | K21: 0 | L21: 0 | M21: 0 | N21: 0 | O21: 0 | P21: 0 | Q21: 0 | R21: 0 | S21: 0 | T21: 0 | U21: 0 | V21: 0 | W21: 0 | X21: 0 | Y21: 0 | Z21: 0 | AA21: 15277 | AB21: 3173720 | AC21: 1243025 | AD21: 210 | AE21: 59500 | AF21: 23005 | AG21: 9917 | AH21: 3318112 | AI21: 202000 | AJ21: 39 | AK21: 15360 | AL21: 2800 | AM21: 3742 | AN21: 1095900 | AO21: 22500 | AP21: 122 | AQ21: 50100 | AR21: 600 | AS21: 7399 | AT21: 2621074 | AU21: 6700 | AV21: 71 | AW21: 39336 | AX21: 300 | AY21: 9535 | AZ21: 3388440 | BA21: 8400 | BB21: 104 | BC21: 51720 | BD21: 0 | BE21: 8 | BF21: 2880 | BG21: 0 | BH21: 4 | BI21: 1920 | BJ21: 0 | BK21: 30 | BL21: 8800 | BM21: 0 | BN21: 3 | BO21: 1200 | BP21: 0 | BQ21: 120 | BR21: 1708954 | BS21: 15337392 | BT21: =L21+U21+AB21+AE21+AN21+AQ21 -> 4379220 | BU21: =AH21+AK21 -> 3333472 | BV21: =AT21+AW21 -> 2660410 | BW21: =+AZ21+BC21 -> 3440160 | BX21: =BF21+BI21 -> 4800 | BY21: =+BL21+BO21 -> 10000 | BZ21: =M21+AC21+AF21+AI21+AL21+AO21+AR21+K21+AU21+AX21+BA21+BD21+BG21+BJ21+BM21+BP21 -> 1509330 | CA21: =IF((BT21+BU21+BZ21+BV21+BW21+BX21+BY21)=BS21,BS21-BR21,"?""") -> 13628438 | CB21: =ROUND(CA21*$CB$3,) -> 8177063 | CD21: =CB21+CC21 -> 8177063 | CE21: =A21 -> 남제 | CF21: =SUBSTITUTE(CE21," ","") -> 남제 | CG21: =CE21=CF21 -> TRUE | CH21: =CF21 -> 남제 | CI21: =IFERROR(_xlfn.XLOOKUP(CH21,$CF$5:$CF$60,$CD$5:$CD$60),"") -> 8177063 | CJ21: MG | CK21: =SUMIFS('컨텐츠별 매출 통계'!CV:CV,'컨텐츠별 매출 통계'!A:A,'작품별 집계'!A21,'컨텐츠별 매출 통계'!CF:CF,"2026-01") -> 8177063 | CL21: =CD21-CK21 -> 0
A22: 레벨999 고블린 | B22: 629975 | D22: 더그림엔터테인먼트_브랜드 | E22: 곰곰 | F22: 다피/곰곰 | G22: 15세 이상 이용가능 | H22: 2026.01.26 | I22: 0 | J22: 0 | K22: 0 | L22: 0 | M22: 0 | N22: 0 | O22: 0 | P22: 0 | Q22: 0 | R22: 0 | S22: 0 | T22: 0 | U22: 0 | V22: 0 | W22: 0 | X22: 0 | Y22: 0 | Z22: 0 | AA22: 14889 | AB22: 2714420 | AC22: 1538945 | AD22: 209 | AE22: 61500 | AF22: 34105 | AG22: 8129 | AH22: 2677453 | AI22: 196000 | AJ22: 7 | AK22: 0 | AL22: 2600 | AM22: 5846 | AN22: 1710800 | AO22: 35000 | AP22: 84 | AQ22: 35800 | AR22: 1200 | AS22: 8218 | AT22: 2906764 | AU22: 6700 | AV22: 50 | AW22: 30400 | AX22: 0 | AY22: 8782 | AZ22: 3127200 | BA22: 4200 | BB22: 55 | BC22: 28320 | BD22: 400 | BE22: 19 | BF22: 6840 | BG22: 0 | BH22: 4 | BI22: 1920 | BJ22: 0 | BK22: 18 | BL22: 5200 | BM22: 0 | BN22: 0 | BO22: 0 | BP22: 0 | BQ22: 0 | BR22: 1518105.5 | BS22: 15125767 | BT22: =L22+U22+AB22+AE22+AN22+AQ22 -> 4522520 | BU22: =AH22+AK22 -> 2677453 | BV22: =AT22+AW22 -> 2937164 | BW22: =+AZ22+BC22 -> 3155520 | BX22: =BF22+BI22 -> 8760 | BY22: =+BL22+BO22 -> 5200 | BZ22: =M22+AC22+AF22+AI22+AL22+AO22+AR22+K22+AU22+AX22+BA22+BD22+BG22+BJ22+BM22+BP22 -> 1819150 | CA22: =IF((BT22+BU22+BZ22+BV22+BW22+BX22+BY22)=BS22,BS22-BR22,"?""") -> 13607662 | CB22: =ROUND(CA22*$CB$3,) -> 8164597 | CD22: =CB22+CC22 -> 8164597 | CE22: =A22 -> 레벨999 고블린 | CF22: =SUBSTITUTE(CE22," ","") -> 레벨999고블린 | CG22: =CE22=CF22 -> FALSE | CH22: =CF22 -> 레벨999고블린 | CI22: =IFERROR(_xlfn.XLOOKUP(CH22,$CF$5:$CF$60,$CD$5:$CD$60),"") -> 8164597 | CJ22: MG | CK22: =SUMIFS('컨텐츠별 매출 통계'!CV:CV,'컨텐츠별 매출 통계'!A:A,'작품별 집계'!A22,'컨텐츠별 매출 통계'!CF:CF,"2026-01") -> 8164597 | CL22: =CD22-CK22 -> 0
A23: 악귀나찰 | B23: 656046 | D23: 더그림엔터테인먼트_브랜드 | E23: 김구름 | F23: 김숭늉/김구름 | G23: 15세 이상 이용가능 | H23: 2026.01.14 | I23: 0 | J23: 0 | K23: 0 | L23: 0 | M23: 0 | N23: 0 | O23: 0 | P23: 0 | Q23: 0 | R23: 0 | S23: 0 | T23: 0 | U23: 0 | V23: 0 | W23: 0 | X23: 0 | Y23: 0 | Z23: 0 | AA23: 13740 | AB23: 2615720 | AC23: 1341680 | AD23: 67 | AE23: 16400 | AF23: 11095 | AG23: 9908 | AH23: 3223145 | AI23: 275000 | AJ23: 14 | AK23: 5280 | AL23: 1200 | AM23: 2698 | AN23: 789300 | AO23: 17100 | AP23: 30 | AQ23: 17200 | AR23: 700 | AS23: 6249 | AT23: 2218402 | AU23: 3700 | AV23: 26 | AW23: 13440 | AX23: 0 | AY23: 7790 | AZ23: 2773920 | BA23: 4800 | BB23: 40 | BC23: 21000 | BD23: 0 | BE23: 2 | BF23: 720 | BG23: 0 | BH23: 0 | BI23: 0 | BJ23: 0 | BK23: 39 | BL23: 11700 | BM23: 0 | BN23: 6 | BO23: 2400 | BP23: 0 | BQ23: 0 | BR23: 1548585.7 | BS23: 13363902 | BT23: =L23+U23+AB23+AE23+AN23+AQ23 -> 3438620 | BU23: =AH23+AK23 -> 3228425 | BV23: =AT23+AW23 -> 2231842 | BW23: =+AZ23+BC23 -> 2794920 | BX23: =BF23+BI23 -> 720 | BY23: =+BL23+BO23 -> 14100 | BZ23: =M23+AC23+AF23+AI23+AL23+AO23+AR23+K23+AU23+AX23+BA23+BD23+BG23+BJ23+BM23+BP23 -> 1655275 | CA23: =IF((BT23+BU23+BZ23+BV23+BW23+BX23+BY23)=BS23,BS23-BR23,"?""") -> 11815316 | CB23: =ROUND(CA23*$CB$3,) -> 7089190 | CD23: =CB23+CC23 -> 7089190 | CE23: =A23 -> 악귀나찰 | CF23: =SUBSTITUTE(CE23," ","") -> 악귀나찰 | CG23: =CE23=CF23 -> TRUE | CH23: =CF23 -> 악귀나찰 | CI23: =IFERROR(_xlfn.XLOOKUP(CH23,$CF$5:$CF$60,$CD$5:$CD$60),"") -> 7089190 | CJ23: MG | CK23: =SUMIFS('컨텐츠별 매출 통계'!CV:CV,'컨텐츠별 매출 통계'!A:A,'작품별 집계'!A23,'컨텐츠별 매출 통계'!CF:CF,"2026-01") -> 7089190 | CL23: =CD23-CK23 -> 0
A24: 용사생활기록부 | B24: 642007 | D24: 더그림엔터테인먼트_브랜드 | E24: 땅콩 | F24: 땅콩 | G24: 15세 이상 이용가능 | H24: 2026.01.31 | I24: 0 | J24: 0 | K24: 0 | L24: 0 | M24: 0 | N24: 0 | O24: 0 | P24: 0 | Q24: 0 | R24: 0 | S24: 0 | T24: 0 | U24: 0 | V24: 0 | W24: 0 | X24: 0 | Y24: 0 | Z24: 0 | AA24: 14029 | AB24: 2311200 | AC24: 1661175 | AD24: 1945 | AE24: 465700 | AF24: 342495 | AG24: 3894 | AH24: 1216915 | AI24: 143400 | AJ24: 188 | AK24: 41840 | AL24: 38000 | AM24: 4285 | AN24: 1255200 | AO24: 23800 | AP24: 722 | AQ24: 311100 | AR24: 9300 | AS24: 6754 | AT24: 2369037 | AU24: 6800 | AV24: 436 | AW24: 222600 | AX24: 400 | AY24: 5875 | AZ24: 2069280 | BA24: 11300 | BB24: 425 | BC24: 208920 | BD24: 1000 | BE24: 5 | BF24: 1800 | BG24: 0 | BH24: 12 | BI24: 5760 | BJ24: 0 | BK24: 107 | BL24: 30800 | BM24: 0 | BN24: 1 | BO24: 400 | BP24: 0 | BQ24: 130 | BR24: 977405.1 | BS24: 12748222 | BT24: =L24+U24+AB24+AE24+AN24+AQ24 -> 4343200 | BU24: =AH24+AK24 -> 1258755 | BV24: =AT24+AW24 -> 2591637 | BW24: =+AZ24+BC24 -> 2278200 | BX24: =BF24+BI24 -> 7560 | BY24: =+BL24+BO24 -> 31200 | BZ24: =M24+AC24+AF24+AI24+AL24+AO24+AR24+K24+AU24+AX24+BA24+BD24+BG24+BJ24+BM24+BP24 -> 2237670 | CA24: =IF((BT24+BU24+BZ24+BV24+BW24+BX24+BY24)=BS24,BS24-BR24,"?""") -> 11770817 | CB24: =ROUND(CA24*$CB$3,) -> 7062490 | CD24: =CB24+CC24 -> 7062490 | CE24: =A24 -> 용사생활기록부 | CF24: =SUBSTITUTE(CE24," ","") -> 용사생활기록부 | CG24: =CE24=CF24 -> TRUE | CH24: =CF24 -> 용사생활기록부 | CI24: =IFERROR(_xlfn.XLOOKUP(CH24,$CF$5:$CF$60,$CD$5:$CD$60),"") -> 7062490 | CJ24: MG | CK24: =SUMIFS('컨텐츠별 매출 통계'!CV:CV,'컨텐츠별 매출 통계'!A:A,'작품별 집계'!A24,'컨텐츠별 매출 통계'!CF:CF,"2026-01") -> 7062490 | CL24: =CD24-CK24 -> 0
A25: 퀘스트지상주의 | B25: 449359 | D25: 더그림엔터테인먼트_브랜드 | E25: 박만사, 태완 | F25: 박만사 | G25: 15세 이상 이용가능 | H25: 2025.02.02 | I25: 0 | J25: 208338 | K25: 0 | L25: 0 | M25: 0 | N25: 0 | O25: 0 | P25: 0 | Q25: 0 | R25: 0 | S25: 0 | T25: 0 | U25: 0 | V25: 0 | W25: 0 | X25: 0 | Y25: 0 | Z25: 0 | AA25: 6379 | AB25: 916900 | AC25: 939685 | AD25: 592 | AE25: 243800 | AF25: 48640 | AG25: 5999 | AH25: 1876338 | AI25: 231500 | AJ25: 214 | AK25: 99960 | AL25: 1700 | AM25: 610 | AN25: 175900 | AO25: 6300 | AP25: 26 | AQ25: 22300 | AR25: 0 | AS25: 7805 | AT25: 2766010 | AU25: 6600 | AV25: 233 | AW25: 237560 | AX25: 0 | AY25: 4535 | AZ25: 1621080 | BA25: 1000 | BB25: 168 | BC25: 91560 | BD25: 0 | BE25: 7 | BF25: 2520 | BG25: 0 | BH25: 0 | BI25: 0 | BJ25: 0 | BK25: 455 | BL25: 135700 | BM25: 0 | BN25: 0 | BO25: 0 | BP25: 0 | BQ25: 36 | BR25: 1108706.5 | BS25: 9425053 | BT25: =L25+U25+AB25+AE25+AN25+AQ25 -> 1358900 | BU25: =AH25+AK25 -> 1976298 | BV25: =AT25+AW25 -> 3003570 | BW25: =+AZ25+BC25 -> 1712640 | BX25: =BF25+BI25 -> 2520 | BY25: =+BL25+BO25 -> 135700 | BZ25: =M25+AC25+AF25+AI25+AL25+AO25+AR25+K25+AU25+AX25+BA25+BD25+BG25+BJ25+BM25+BP25 -> 1235425 | CA25: =IF((BT25+BU25+BZ25+BV25+BW25+BX25+BY25)=BS25,BS25-BR25,"?""") -> 8316346.5 | CB25: =ROUND(CA25*$CB$3,) -> 4989808 | CD25: =CB25+CC25 -> 4989808 | CE25: =A25 -> 퀘스트지상주의 | CF25: =SUBSTITUTE(CE25," ","") -> 퀘스트지상주의 | CG25: =CE25=CF25 -> TRUE | CH25: =CF25 -> 퀘스트지상주의 | CI25: =IFERROR(_xlfn.XLOOKUP(CH25,$CF$5:$CF$60,$CD$5:$CD$60),"") -> 4989808 | CJ25: MG | CK25: =SUMIFS('컨텐츠별 매출 통계'!CV:CV,'컨텐츠별 매출 통계'!A:A,'작품별 집계'!A25,'컨텐츠별 매출 통계'!CF:CF,"2026-01") -> 4989808 | CL25: =CD25-CK25 -> 0
A26: 강제소집 | B26: 624713 | D26: 더그림엔터테인먼트_브랜드 | E26: GArt | F26: 남자의이야기/GArt | G26: 19세 이상 이용가능 | H26: 2025.12.23 | I26: 0 | J26: 0 | K26: 0 | L26: 0 | M26: 0 | N26: 0 | O26: 0 | P26: 0 | Q26: 0 | R26: 0 | S26: 0 | T26: 0 | U26: 0 | V26: 0 | W26: 0 | X26: 0 | Y26: 0 | Z26: 0 | AA26: 7332 | AB26: 1005480 | AC26: 1045055 | AD26: 14 | AE26: 6000 | AF26: 3125 | AG26: 4862 | AH26: 1483936 | AI26: 205500 | AJ26: 2 | AK26: 600 | AL26: 500 | AM26: 927 | AN26: 270200 | AO26: 5500 | AP26: 5 | AQ26: 3500 | AR26: 0 | AS26: 2065 | AT26: 727836 | AU26: 200 | AV26: 5 | AW26: 3000 | AX26: 0 | AY26: 2792 | AZ26: 984960 | BA26: 700 | BB26: 6 | BC26: 30600 | BD26: 0 | BE26: 4 | BF26: 1440 | BG26: 0 | BH26: 0 | BI26: 0 | BJ26: 0 | BK26: 8 | BL26: 2400 | BM26: 0 | BN26: 0 | BO26: 0 | BP26: 0 | BQ26: 72 | BR26: 648873.2 | BS26: 5780532 | BT26: =L26+U26+AB26+AE26+AN26+AQ26 -> 1285180 | BU26: =AH26+AK26 -> 1484536 | BV26: =AT26+AW26 -> 730836 | BW26: =+AZ26+BC26 -> 1015560 | BX26: =BF26+BI26 -> 1440 | BY26: =+BL26+BO26 -> 2400 | BZ26: =M26+AC26+AF26+AI26+AL26+AO26+AR26+K26+AU26+AX26+BA26+BD26+BG26+BJ26+BM26+BP26 -> 1260580 | CA26: =IF((BT26+BU26+BZ26+BV26+BW26+BX26+BY26)=BS26,BS26-BR26,"?""") -> 5131658.8 | CB26: =ROUND(CA26*$CB$3,) -> 3078995 | CD26: =CB26+CC26 -> 3078995 | CE26: =A26 -> 강제소집 | CF26: =SUBSTITUTE(CE26," ","") -> 강제소집 | CG26: =CE26=CF26 -> TRUE | CH26: =CF26 -> 강제소집 | CI26: =IFERROR(_xlfn.XLOOKUP(CH26,$CF$5:$CF$60,$CD$5:$CD$60),"") -> 3078995 | CJ26: MG | CK26: =SUMIFS('컨텐츠별 매출 통계'!CV:CV,'컨텐츠별 매출 통계'!A:A,'작품별 집계'!A26,'컨텐츠별 매출 통계'!CF:CF,"2026-01") -> 3078995 | CL26: =CD26-CK26 -> 0
... A28: 유쾌한 왕따(재) | B28: 512152 | D28: 더그림엔터테인먼트_브랜드 | E28: 김숭늉 | F28: 박만사 | G28: 19세 이상 이용가능 | H28: 2024.03.08 | I28: 0 | J28: 42018 | K28: 0 | L28: 0 | M28: 0 | N28: 0 | O28: 0 | P28: 0 | Q28: 0 | R28: 0 | S28: 0 | T28: 0 | U28: 0 | V28: 0 | W28: 0 | X28: 0 | Y28: 0 | Z28: 0 | AA28: 3848 | AB28: 445900 | AC28: 292400 | AD28: 77 | AE28: 41600 | AF28: 22180 | AG28: 5030 | AH28: 1060691 | AI28: 123400 | AJ28: 7 | AK28: 0 | AL28: 2800 | AM28: 1056 | AN28: 206900 | AO28: 3900 | AP28: 7 | AQ28: 5200 | AR28: 0 | AS28: 1597 | AT28: 384186 | AU28: 300 | AV28: 33 | AW28: 14640 | AX28: 0 | AY28: 2462 | AZ28: 586680 | BA28: 2000 | BB28: 53 | BC28: 72840 | BD28: 0 | BE28: 0 | BF28: 0 | BG28: 0 | BH28: 0 | BI28: 0 | BJ28: 0 | BK28: 16 | BL28: 3200 | BM28: 0 | BN28: 0 | BO28: 0 | BP28: 0 | BQ28: 0 | BR28: 438914.7 | BS28: 3268817 | BT28: =L28+U28+AB28+AE28+AN28+AQ28 -> 699600 | BU28: =AH28+AK28 -> 1060691 | BV28: =AT28+AW28 -> 398826 | BW28: =+AZ28+BC28 -> 659520 | BX28: =BF28+BI28 -> 0 | BY28: =+BL28+BO28 -> 3200 | BZ28: =M28+AC28+AF28+AI28+AL28+AO28+AR28+K28+AU28+AX28+BA28+BD28+BG28+BJ28+BM28+BP28 -> 446980 | CA28: =IF((BT28+BU28+BZ28+BV28+BW28+BX28+BY28)=BS28,BS28-BR28,"?""") -> 2829902.3 | CB28: =ROUND(CA28*$CB$3,) -> 1697941 | CD28: =CB28+CC28 -> 1697941 | CE28: =A28 -> 유쾌한 왕따(재) | CF28: =SUBSTITUTE(CE28," ","") -> 유쾌한왕따(재) | CG28: =CE28=CF28 -> FALSE | CH28: =CF28 -> 유쾌한왕따(재) | CI28: =IFERROR(_xlfn.XLOOKUP(CH28,$CF$5:$CF$60,$CD$5:$CD$60),"") -> 1697941 | CJ28: MG | CK28: =SUMIFS('컨텐츠별 매출 통계'!CV:CV,'컨텐츠별 매출 통계'!A:A,'작품별 집계'!A28,'컨텐츠별 매출 통계'!CF:CF,"2026-01") -> 1697941 | CL28: =CD28-CK28 -> 0
A29: 촉법소년 | B29: 503855 | D29: 더그림엔터테인먼트_브랜드 | E29: 박만사, 남자의 이야기 | F29: 정종택 | G29: 15세 이상 이용가능 | H29: 2024.09.18 | I29: 0 | J29: 62479 | K29: 0 | L29: 0 | M29: 0 | N29: 0 | O29: 0 | P29: 0 | Q29: 0 | R29: 0 | S29: 0 | T29: 0 | U29: 0 | V29: 0 | W29: 0 | X29: 0 | Y29: 0 | Z29: 0 | AA29: 1240 | AB29: 215900 | AC29: 137410 | AD29: 276 | AE29: 104600 | AF29: 54355 | AG29: 2174 | AH29: 718223 | AI29: 50900 | AJ29: 80 | AK29: 46200 | AL29: 1200 | AM29: 463 | AN29: 136600 | AO29: 2000 | AP29: 134 | AQ29: 103900 | AR29: 600 | AS29: 1818 | AT29: 648137 | AU29: 1000 | AV29: 79 | AW29: 95880 | AX29: 0 | AY29: 1644 | AZ29: 588600 | BA29: 300 | BB29: 8 | BC29: 24240 | BD29: 500 | BE29: 6 | BF29: 2160 | BG29: 0 | BH29: 69 | BI29: 41400 | BJ29: 0 | BK29: 67 | BL29: 19900 | BM29: 0 | BN29: 1 | BO29: 500 | BP29: 0 | BQ29: 216 | BR29: 382252.5 | BS29: 2994505 | BT29: =L29+U29+AB29+AE29+AN29+AQ29 -> 561000 | BU29: =AH29+AK29 -> 764423 | BV29: =AT29+AW29 -> 744017 | BW29: =+AZ29+BC29 -> 612840 | BX29: =BF29+BI29 -> 43560 | BY29: =+BL29+BO29 -> 20400 | BZ29: =M29+AC29+AF29+AI29+AL29+AO29+AR29+K29+AU29+AX29+BA29+BD29+BG29+BJ29+BM29+BP29 -> 248265 | CA29: =IF((BT29+BU29+BZ29+BV29+BW29+BX29+BY29)=BS29,BS29-BR29,"?""") -> 2612252.5 | CB29: =ROUND(CA29*$CB$3,) -> 1567352 | CC29: -1 | CD29: =CB29+CC29 -> 1567351 | CE29: =A29 -> 촉법소년 | CF29: =SUBSTITUTE(CE29," ","") -> 촉법소년 | CG29: =CE29=CF29 -> TRUE | CH29: =CF29 -> 촉법소년 | CI29: =IFERROR(_xlfn.XLOOKUP(CH29,$CF$5:$CF$60,$CD$5:$CD$60),"") -> 1567351 | CJ29: MG | CK29: =SUMIFS('컨텐츠별 매출 통계'!CV:CV,'컨텐츠별 매출 통계'!A:A,'작품별 집계'!A29,'컨텐츠별 매출 통계'!CF:CF,"2026-01") -> 1567351 | CL29: =CD29-CK29 -> 0
A30: 진주 | B30: 535549 | D30: 더그림엔터테인먼트_브랜드 | E30: 백두 | F30: 박만사 | G30: 15세 이상 이용가능 | H30: 2025.02.02 | I30: 0 | J30: 26054 | K30: 0 | L30: 0 | M30: 0 | N30: 0 | O30: 0 | P30: 0 | Q30: 0 | R30: 0 | S30: 0 | T30: 0 | U30: 0 | V30: 0 | W30: 0 | X30: 0 | Y30: 0 | Z30: 0 | AA30: 1395 | AB30: 190400 | AC30: 209435 | AD30: 238 | AE30: 34800 | AF30: 75490 | AG30: 1024 | AH30: 335730 | AI30: 27200 | AJ30: 175 | AK30: 48960 | AL30: 28700 | AM30: 255 | AN30: 73900 | AO30: 2100 | AP30: 41 | AQ30: 16000 | AR30: 400 | AS30: 887 | AT30: 313920 | AU30: 2000 | AV30: 200 | AW30: 95880 | AX30: 0 | AY30: 1238 | AZ30: 441120 | BA30: 1000 | BB30: 303 | BC30: 144720 | BD30: 0 | BE30: 15 | BF30: 5400 | BG30: 0 | BH30: 33 | BI30: 15240 | BJ30: 0 | BK30: 0 | BL30: 0 | BM30: 0 | BN30: 0 | BO30: 0 | BP30: 0 | BQ30: 0 | BR30: 220216.8 | BS30: 2062395 | BT30: =L30+U30+AB30+AE30+AN30+AQ30 -> 315100 | BU30: =AH30+AK30 -> 384690 | BV30: =AT30+AW30 -> 409800 | BW30: =+AZ30+BC30 -> 585840 | BX30: =BF30+BI30 -> 20640 | BY30: =+BL30+BO30 -> 0 | BZ30: =M30+AC30+AF30+AI30+AL30+AO30+AR30+K30+AU30+AX30+BA30+BD30+BG30+BJ30+BM30+BP30 -> 346325 | CA30: =IF((BT30+BU30+BZ30+BV30+BW30+BX30+BY30)=BS30,BS30-BR30,"?""") -> 1842178.2 | CB30: =ROUND(CA30*$CB$3,) -> 1105307 | CD30: =CB30+CC30 -> 1105307 | CE30: =A30 -> 진주 | CF30: =SUBSTITUTE(CE30," ","") -> 진주 | CG30: =CE30=CF30 -> TRUE | CH30: =CF30 -> 진주 | CI30: =IFERROR(_xlfn.XLOOKUP(CH30,$CF$5:$CF$60,$CD$5:$CD$60),"") -> 1105307 | CJ30: MG | CK30: =SUMIFS('컨텐츠별 매출 통계'!CV:CV,'컨텐츠별 매출 통계'!A:A,'작품별 집계'!A30,'컨텐츠별 매출 통계'!CF:CF,"2026-01") -> 1105307 | CL30: =CD30-CK30 -> 0
A31: 여고생 드래곤 | B31: 452717 | D31: 더그림엔터테인먼트_브랜드 | E31: 땅콩 | F31: 땅콩 | G31: 12세 이상 이용가능 | H31: 2022.12.27 | I31: 0 | J31: 59276 | K31: 0 | L31: 0 | M31: 0 | N31: 0 | O31: 0 | P31: 0 | Q31: 0 | R31: 0 | S31: 0 | T31: 0 | U31: 0 | V31: 0 | W31: 0 | X31: 0 | Y31: 0 | Z31: 0 | AA31: 2072 | AB31: 187200 | AC31: 144845 | AD31: 1036 | AE31: 277400 | AF31: 184460 | AG31: 1086 | AH31: 207139 | AI31: 14100 | AJ31: 197 | AK31: 58080 | AL31: 39800 | AM31: 677 | AN31: 88300 | AO31: 1500 | AP31: 53 | AQ31: 32300 | AR31: 0 | AS31: 1215 | AT31: 202237 | AU31: 0 | AV31: 17 | AW31: 120600 | AX31: 0 | AY31: 744 | AZ31: 176040 | BA31: 500 | BB31: 20 | BC31: 43320 | BD31: 0 | BE31: 0 | BF31: 0 | BG31: 0 | BH31: 0 | BI31: 0 | BJ31: 0 | BK31: 3 | BL31: 4300 | BM31: 0 | BN31: 0 | BO31: 0 | BP31: 0 | BQ31: 0 | BR31: 149792.8 | BS31: 1782121 | BT31: =L31+U31+AB31+AE31+AN31+AQ31 -> 585200 | BU31: =AH31+AK31 -> 265219 | BV31: =AT31+AW31 -> 322837 | BW31: =+AZ31+BC31 -> 219360 | BX31: =BF31+BI31 -> 0 | BY31: =+BL31+BO31 -> 4300 | BZ31: =M31+AC31+AF31+AI31+AL31+AO31+AR31+K31+AU31+AX31+BA31+BD31+BG31+BJ31+BM31+BP31 -> 385205 | CA31: =IF((BT31+BU31+BZ31+BV31+BW31+BX31+BY31)=BS31,BS31-BR31,"?""") -> 1632328.2 | CB31: =ROUND(CA31*$CB$3,) -> 979397 | CD31: =CB31+CC31 -> 979397 | CE31: =A31 -> 여고생 드래곤 | CF31: =SUBSTITUTE(CE31," ","") -> 여고생드래곤 | CG31: =CE31=CF31 -> FALSE | CH31: =CF31 -> 여고생드래곤 | CI31: =IFERROR(_xlfn.XLOOKUP(CH31,$CF$5:$CF$60,$CD$5:$CD$60),"") -> 979397 | CJ31: MG | CK31: =SUMIFS('컨텐츠별 매출 통계'!CV:CV,'컨텐츠별 매출 통계'!A:A,'작품별 집계'!A31,'컨텐츠별 매출 통계'!CF:CF,"2026-01") -> 979397 | CL31: =CD31-CK31 -> 0
A32: 얼짱시대 | B32: 518182 | D32: 더그림엔터테인먼트_브랜드 | E32: 박만사 | F32: 박만사 | G32: 15세 이상 이용가능 | H32: 2024.08.02 | I32: 0 | J32: 23049 | K32: 0 | L32: 0 | M32: 0 | N32: 0 | O32: 0 | P32: 0 | Q32: 0 | R32: 0 | S32: 0 | T32: 0 | U32: 0 | V32: 0 | W32: 0 | X32: 0 | Y32: 0 | Z32: 0 | AA32: 747 | AB32: 106100 | AC32: 106255 | AD32: 10 | AE32: 6500 | AF32: 3600 | AG32: 1270 | AH32: 423630 | AI32: 24600 | AJ32: 62 | AK32: 3840 | AL32: 21600 | AM32: 171 | AN32: 50100 | AO32: 900 | AP32: 1 | AQ32: 400 | AR32: 0 | AS32: 496 | AT32: 174340 | AU32: 1000 | AV32: 1 | AW32: 21480 | AX32: 0 | AY32: 325 | AZ32: 114000 | BA32: 1000 | BB32: 0 | BC32: 0 | BD32: 0 | BE32: 0 | BF32: 0 | BG32: 0 | BH32: 0 | BI32: 0 | BJ32: 0 | BK32: 44 | BL32: 13200 | BM32: 0 | BN32: 0 | BO32: 0 | BP32: 0 | BQ32: 0 | BR32: 164956 | BS32: 1072545 | BT32: =L32+U32+AB32+AE32+AN32+AQ32 -> 163100 | BU32: =AH32+AK32 -> 427470 | BV32: =AT32+AW32 -> 195820 | BW32: =+AZ32+BC32 -> 114000 | BX32: =BF32+BI32 -> 0 | BY32: =+BL32+BO32 -> 13200 | BZ32: =M32+AC32+AF32+AI32+AL32+AO32+AR32+K32+AU32+AX32+BA32+BD32+BG32+BJ32+BM32+BP32 -> 158955 | CA32: =IF((BT32+BU32+BZ32+BV32+BW32+BX32+BY32)=BS32,BS32-BR32,"?""") -> 907589 | CB32: =ROUND(CA32*$CB$3,) -> 544553 | CD32: =CB32+CC32 -> 544553 | CE32: =A32 -> 얼짱시대 | CF32: =SUBSTITUTE(CE32," ","") -> 얼짱시대 | CG32: =CE32=CF32 -> TRUE | CH32: =CF32 -> 얼짱시대 | CI32: =IFERROR(_xlfn.XLOOKUP(CH32,$CF$5:$CF$60,$CD$5:$CD$60),"") -> 544553 | CJ32: MG | CK32: =SUMIFS('컨텐츠별 매출 통계'!CV:CV,'컨텐츠별 매출 통계'!A:A,'작품별 집계'!A32,'컨텐츠별 매출 통계'!CF:CF,"2026-01") -> 544553 | CL32: =CD32-CK32 -> 0
A33: 좋아? 죽어! | B33: 549371 | D33: 더그림엔터테인먼트_브랜드 | E33: 죠 | F33: 박만사 | G33: 19세 이상 이용가능 | H33: 2025.02.24 | I33: 0 | J33: 20722 | K33: 0 | L33: 0 | M33: 0 | N33: 0 | O33: 0 | P33: 0 | Q33: 0 | R33: 0 | S33: 0 | T33: 0 | U33: 0 | V33: 0 | W33: 0 | X33: 0 | Y33: 0 | Z33: 0 | AA33: 986 | AB33: 113100 | AC33: 76955 | AD33: 49 | AE33: 10800 | AF33: 3315 | AG33: 2171 | AH33: 459720 | AI33: 50400 | AJ33: 11 | AK33: 0 | AL33: 3300 | AM33: 118 | AN33: 23600 | AO33: 0 | AP33: 0 | AQ33: 0 | AR33: 0 | AS33: 583 | AT33: 139572 | AU33: 0 | AV33: 0 | AW33: 0 | AX33: 0 | AY33: 642 | AZ33: 153720 | BA33: 200 | BB33: 0 | BC33: 0 | BD33: 0 | BE33: 0 | BF33: 0 | BG33: 0 | BH33: 0 | BI33: 0 | BJ33: 0 | BK33: 100 | BL33: 20000 | BM33: 0 | BN33: 0 | BO33: 0 | BP33: 0 | BQ33: 0 | BR33: 173133 | BS33: 1054682 | BT33: =L33+U33+AB33+AE33+AN33+AQ33 -> 147500 | BU33: =AH33+AK33 -> 459720 | BV33: =AT33+AW33 -> 139572 | BW33: =+AZ33+BC33 -> 153720 | BX33: =BF33+BI33 -> 0 | BY33: =+BL33+BO33 -> 20000 | BZ33: =M33+AC33+AF33+AI33+AL33+AO33+AR33+K33+AU33+AX33+BA33+BD33+BG33+BJ33+BM33+BP33 -> 134170 | CA33: =IF((BT33+BU33+BZ33+BV33+BW33+BX33+BY33)=BS33,BS33-BR33,"?""") -> 881549 | CB33: =ROUND(CA33*$CB$3,) -> 528929 | CD33: =CB33+CC33 -> 528929 | CE33: =A33 -> 좋아? 죽어! | CF33: =SUBSTITUTE(CE33," ","") -> 좋아?죽어! | CG33: =CE33=CF33 -> FALSE | CH33: =CF33 -> 좋아?죽어! | CI33: =IFERROR(_xlfn.XLOOKUP(CH33,$CF$5:$CF$60,$CD$5:$CD$60),"") -> 528929 | CJ33: MG | CK33: =SUMIFS('컨텐츠별 매출 통계'!CV:CV,'컨텐츠별 매출 통계'!A:A,'작품별 집계'!A33,'컨텐츠별 매출 통계'!CF:CF,"2026-01") -> 528929 | CL33: =CD33-CK33 -> 0
A34: 사형소년 | B34: 470703 | D34: 더그림엔터테인먼트_브랜드 | E34: 광산 | F34: 박만사 | G34: 15세 이상 이용가능 | H34: 2023.10.28 | I34: 0 | J34: 15302 | K34: 0 | L34: 0 | M34: 0 | N34: 0 | O34: 0 | P34: 0 | Q34: 0 | R34: 0 | S34: 0 | T34: 0 | U34: 0 | V34: 0 | W34: 0 | X34: 0 | Y34: 0 | Z34: 0 | AA34: 546 | AB34: 62900 | AC34: 96840 | AD34: 6 | AE34: 0 | AF34: 3000 | AG34: 901 | AH34: 274680 | AI34: 40500 | AJ34: 83 | AK34: 66840 | AL34: 7500 | AM34: 154 | AN34: 45000 | AO34: 1100 | AP34: 67 | AQ34: 32900 | AR34: 600 | AS34: 399 | AT34: 140580 | AU34: 0 | AV34: 5 | AW34: 3000 | AX34: 0 | AY34: 522 | AZ34: 186720 | BA34: 0 | BB34: 0 | BC34: 0 | BD34: 0 | BE34: 0 | BF34: 0 | BG34: 0 | BH34: 0 | BI34: 0 | BJ34: 0 | BK34: 0 | BL34: 0 | BM34: 0 | BN34: 0 | BO34: 0 | BP34: 0 | BQ34: 0 | BR34: 137842.8 | BS34: 962160 | BT34: =L34+U34+AB34+AE34+AN34+AQ34 -> 140800 | BU34: =AH34+AK34 -> 341520 | BV34: =AT34+AW34 -> 143580 | BW34: =+AZ34+BC34 -> 186720 | BX34: =BF34+BI34 -> 0 | BY34: =+BL34+BO34 -> 0 | BZ34: =M34+AC34+AF34+AI34+AL34+AO34+AR34+K34+AU34+AX34+BA34+BD34+BG34+BJ34+BM34+BP34 -> 149540 | CA34: =IF((BT34+BU34+BZ34+BV34+BW34+BX34+BY34)=BS34,BS34-BR34,"?""") -> 824317.2 | CB34: =ROUND(CA34*$CB$3,) -> 494590 | CD34: =CB34+CC34 -> 494590 | CE34: =A34 -> 사형소년 | CF34: =SUBSTITUTE(CE34," ","") -> 사형소년 | CG34: =CE34=CF34 -> TRUE | CH34: =CF34 -> 사형소년 | CI34: =IFERROR(_xlfn.XLOOKUP(CH34,$CF$5:$CF$60,$CD$5:$CD$60),"") -> 494590 | CJ34: MG | CK34: =SUMIFS('컨텐츠별 매출 통계'!CV:CV,'컨텐츠별 매출 통계'!A:A,'작품별 집계'!A34,'컨텐츠별 매출 통계'!CF:CF,"2026-01") -> 494590 | CL34: =CD34-CK34 -> 0
A35: 인생존망2 | B35: 545140 | D35: 더그림엔터테인먼트_브랜드 | E35: 전선욱 | F35: 박만사 | G35: 15세 이상 이용가능 | H35: 2025.02.28 | I35: 0 | J35: 21924 | K35: 0 | L35: 0 | M35: 0 | N35: 0 | O35: 0 | P35: 0 | Q35: 0 | R35: 0 | S35: 0 | T35: 0 | U35: 0 | V35: 0 | W35: 0 | X35: 0 | Y35: 0 | Z35: 0 | AA35: 400 | AB35: 58600 | AC35: 54635 | AD35: 137 | AE35: 44200 | AF35: 31930 | AG35: 796 | AH35: 261068 | AI35: 19900 | AJ35: 24 | AK35: 11280 | AL35: 0 | AM35: 83 | AN35: 24100 | AO35: 600 | AP35: 54 | AQ35: 26400 | AR35: 0 | AS35: 520 | AT35: 185760 | AU35: 0 | AV35: 4 | AW35: 17280 | AX35: 0 | AY35: 292 | AZ35: 102960 | BA35: 1000 | BB35: 49 | BC35: 23520 | BD35: 0 | BE35: 1 | BF35: 360 | BG35: 0 | BH35: 0 | BI35: 0 | BJ35: 0 | BK35: 0 | BL35: 0 | BM35: 0 | BN35: 0 | BO35: 0 | BP35: 0 | BQ35: 0 | BR35: 118019.4 | BS35: 863593 | BT35: =L35+U35+AB35+AE35+AN35+AQ35 -> 153300 | BU35: =AH35+AK35 -> 272348 | BV35: =AT35+AW35 -> 203040 | BW35: =+AZ35+BC35 -> 126480 | BX35: =BF35+BI35 -> 360 | BY35: =+BL35+BO35 -> 0 | BZ35: =M35+AC35+AF35+AI35+AL35+AO35+AR35+K35+AU35+AX35+BA35+BD35+BG35+BJ35+BM35+BP35 -> 108065 | CA35: =IF((BT35+BU35+BZ35+BV35+BW35+BX35+BY35)=BS35,BS35-BR35,"?""") -> 745573.6 | CB35: =ROUND(CA35*$CB$3,) -> 447344 | CD35: =CB35+CC35 -> 447344 | CE35: =A35 -> 인생존망2 | CF35: =SUBSTITUTE(CE35," ","") -> 인생존망2 | CG35: =CE35=CF35 -> TRUE | CH35: =CF35 -> 인생존망2 | CI35: =IFERROR(_xlfn.XLOOKUP(CH35,$CF$5:$CF$60,$CD$5:$CD$60),"") -> 447344 | CJ35: MG | CK35: =SUMIFS('컨텐츠별 매출 통계'!CV:CV,'컨텐츠별 매출 통계'!A:A,'작품별 집계'!A35,'컨텐츠별 매출 통계'!CF:CF,"2026-01") -> 447344 | CL35: =CD35-CK35 -> 0
A36: 신림/남/22 | B36: 450429 | D36: 더그림엔터테인먼트_브랜드 | E36: 박만사 | F36: 박만사 | G36: 19세 이상 이용가능 | H36: 2022.05.28 | I36: 0 | J36: 17827 | K36: 0 | L36: 0 | M36: 0 | N36: 0 | O36: 0 | P36: 0 | Q36: 0 | R36: 0 | S36: 0 | T36: 0 | U36: 0 | V36: 0 | W36: 0 | X36: 0 | Y36: 0 | Z36: 0 | AA36: 559 | AB36: 103100 | AC36: 95650 | AD36: 3 | AE36: 9400 | AF36: 2900 | AG36: 888 | AH36: 335722 | AI36: 41200 | AJ36: 0 | AK36: 0 | AL36: 0 | AM36: 37 | AN36: 12200 | AO36: 0 | AP36: 0 | AQ36: 0 | AR36: 0 | AS36: 239 | AT36: 105293 | AU36: 500 | AV36: 0 | AW36: 0 | AX36: 0 | AY36: 293 | AZ36: 128640 | BA36: 200 | BB36: 4 | BC36: 3960 | BD36: 0 | BE36: 0 | BF36: 0 | BG36: 0 | BH36: 0 | BI36: 0 | BJ36: 0 | BK36: 0 | BL36: 0 | BM36: 0 | BN36: 0 | BO36: 0 | BP36: 0 | BQ36: 37 | BR36: 126919.8 | BS36: 838765 | BT36: =L36+U36+AB36+AE36+AN36+AQ36 -> 124700 | BU36: =AH36+AK36 -> 335722 | BV36: =AT36+AW36 -> 105293 | BW36: =+AZ36+BC36 -> 132600 | BX36: =BF36+BI36 -> 0 | BY36: =+BL36+BO36 -> 0 | BZ36: =M36+AC36+AF36+AI36+AL36+AO36+AR36+K36+AU36+AX36+BA36+BD36+BG36+BJ36+BM36+BP36 -> 140450 | CA36: =IF((BT36+BU36+BZ36+BV36+BW36+BX36+BY36)=BS36,BS36-BR36,"?""") -> 711845.2 | CB36: =ROUND(CA36*$CB$3,) -> 427107 | CD36: =CB36+CC36 -> 427107 | CE36: =A36 -> 신림/남/22 | CF36: =SUBSTITUTE(CE36," ","") -> 신림/남/22 | CG36: =CE36=CF36 -> TRUE | CH36: =CF36 -> 신림/남/22 | CI36: =IFERROR(_xlfn.XLOOKUP(CH36,$CF$5:$CF$60,$CD$5:$CD$60),"") -> 427107 | CJ36: MG | CK36: =SUMIFS('컨텐츠별 매출 통계'!CV:CV,'컨텐츠별 매출 통계'!A:A,'작품별 집계'!A36,'컨텐츠별 매출 통계'!CF:CF,"2026-01") -> 427107 | CL36: =CD36-CK36 -> 0
A37: 벤타블랙 | B37: 593379 | D37: 더그림엔터테인먼트_브랜드 | E37: 신신성 | F37: 신신성 | G37: 15세 이상 이용가능 | H37: 2025.09.28 | I37: 0 | J37: 7068 | K37: 0 | L37: 0 | M37: 0 | N37: 0 | O37: 0 | P37: 0 | Q37: 0 | R37: 0 | S37: 0 | T37: 0 | U37: 0 | V37: 0 | W37: 0 | X37: 0 | Y37: 0 | Z37: 0 | AA37: 672 | AB37: 90260 | AC37: 101515 | AD37: 1 | AE37: 0 | AF37: 2000 | AG37: 456 | AH37: 154314 | AI37: 7400 | AJ37: 0 | AK37: 0 | AL37: 0 | AM37: 173 | AN37: 49400 | AO37: 2300 | AP37: 43 | AQ37: 17200 | AR37: 0 | AS37: 380 | AT37: 132778 | AU37: 0 | AV37: 0 | AW37: 0 | AX37: 0 | AY37: 674 | AZ37: 240840 | BA37: 200 | BB37: 29 | BC37: 13920 | BD37: 0 | BE37: 1 | BF37: 360 | BG37: 0 | BH37: 0 | BI37: 0 | BJ37: 0 | BK37: 0 | BL37: 0 | BM37: 0 | BN37: 0 | BO37: 0 | BP37: 0 | BQ37: 0 | BR37: 87235 | BS37: 812487 | BT37: =L37+U37+AB37+AE37+AN37+AQ37 -> 156860 | BU37: =AH37+AK37 -> 154314 | BV37: =AT37+AW37 -> 132778 | BW37: =+AZ37+BC37 -> 254760 | BX37: =BF37+BI37 -> 360 | BY37: =+BL37+BO37 -> 0 | BZ37: =M37+AC37+AF37+AI37+AL37+AO37+AR37+K37+AU37+AX37+BA37+BD37+BG37+BJ37+BM37+BP37 -> 113415 | CA37: =IF((BT37+BU37+BZ37+BV37+BW37+BX37+BY37)=BS37,BS37-BR37,"?""") -> 725252 | CB37: =ROUND(CA37*$CB$3,) -> 435151 | CD37: =CB37+CC37 -> 435151 | CE37: =A37 -> 벤타블랙 | CF37: =SUBSTITUTE(CE37," ","") -> 벤타블랙 | CG37: =CE37=CF37 -> TRUE | CH37: =CF37 -> 벤타블랙 | CI37: =IFERROR(_xlfn.XLOOKUP(CH37,$CF$5:$CF$60,$CD$5:$CD$60),"") -> 435151 | CJ37: MG | CK37: =SUMIFS('컨텐츠별 매출 통계'!CV:CV,'컨텐츠별 매출 통계'!A:A,'작품별 집계'!A37,'컨텐츠별 매출 통계'!CF:CF,"2026-01") -> 435151 | CL37: =CD37-CK37 -> 0
A38: 궤짝 | B38: 488013 | D38: 더그림엔터테인먼트_브랜드 | E38: 지노 | F38: 박만사 | G38: 15세 이상 이용가능 | H38: 2024.04.15 | I38: 0 | J38: 11196 | K38: 0 | L38: 0 | M38: 0 | N38: 0 | O38: 0 | P38: 0 | Q38: 0 | R38: 0 | S38: 0 | T38: 0 | U38: 0 | V38: 0 | W38: 0 | X38: 0 | Y38: 0 | Z38: 0 | AA38: 1031 | AB38: 74500 | AC38: 122485 | AD38: 121 | AE38: 11700 | AF38: 24945 | AG38: 1125 | AH38: 211356 | AI38: 49800 | AJ38: 72 | AK38: 2160 | AL38: 19800 | AM38: 68 | AN38: 13300 | AO38: 200 | AP38: 2 | AQ38: 600 | AR38: 0 | AS38: 493 | AT38: 117560 | AU38: 200 | AV38: 3 | AW38: 6840 | AX38: 0 | AY38: 284 | AZ38: 67920 | BA38: 0 | BB38: 2 | BC38: 720 | BD38: 0 | BE38: 0 | BF38: 0 | BG38: 0 | BH38: 0 | BI38: 0 | BJ38: 0 | BK38: 0 | BL38: 0 | BM38: 0 | BN38: 0 | BO38: 0 | BP38: 0 | BQ38: 0 | BR38: 85675.4 | BS38: 724086 | BT38: =L38+U38+AB38+AE38+AN38+AQ38 -> 100100 | BU38: =AH38+AK38 -> 213516 | BV38: =AT38+AW38 -> 124400 | BW38: =+AZ38+BC38 -> 68640 | BX38: =BF38+BI38 -> 0 | BY38: =+BL38+BO38 -> 0 | BZ38: =M38+AC38+AF38+AI38+AL38+AO38+AR38+K38+AU38+AX38+BA38+BD38+BG38+BJ38+BM38+BP38 -> 217430 | CA38: =IF((BT38+BU38+BZ38+BV38+BW38+BX38+BY38)=BS38,BS38-BR38,"?""") -> 638410.6 | CB38: =ROUND(CA38*$CB$3,) -> 383046 | CC38: 1 | CD38: =CB38+CC38 -> 383047 | CE38: =A38 -> 궤짝 | CF38: =SUBSTITUTE(CE38," ","") -> 궤짝 | CG38: =CE38=CF38 -> TRUE | CH38: =CF38 -> 궤짝 | CI38: =IFERROR(_xlfn.XLOOKUP(CH38,$CF$5:$CF$60,$CD$5:$CD$60),"") -> 383047 | CJ38: MG | CK38: =SUMIFS('컨텐츠별 매출 통계'!CV:CV,'컨텐츠별 매출 통계'!A:A,'작품별 집계'!A38,'컨텐츠별 매출 통계'!CF:CF,"2026-01") -> 383047 | CL38: =CD38-CK38 -> 0
A39: 룸비니 | B39: 553515 | D39: 더그림엔터테인먼트_브랜드 | E39: 약수 | F39: 박만사 | G39: 15세 이상 이용가능 | H39: 2025.09.17 | I39: 0 | J39: 3645 | K39: 0 | L39: 0 | M39: 0 | N39: 0 | O39: 0 | P39: 0 | Q39: 0 | R39: 0 | S39: 0 | T39: 0 | U39: 0 | V39: 0 | W39: 0 | X39: 0 | Y39: 0 | Z39: 0 | AA39: 541 | AB39: 77900 | AC39: 75145 | AD39: 8 | AE39: 0 | AF39: 23200 | AG39: 497 | AH39: 177768 | AI39: 4600 | AJ39: 0 | AK39: 0 | AL39: 0 | AM39: 39 | AN39: 10800 | AO39: 900 | AP39: 0 | AQ39: 0 | AR39: 0 | AS39: 474 | AT39: 165166 | AU39: 300 | AV39: 0 | AW39: 0 | AX39: 0 | AY39: 410 | AZ39: 145920 | BA39: 300 | BB39: 0 | BC39: 0 | BD39: 0 | BE39: 0 | BF39: 0 | BG39: 0 | BH39: 0 | BI39: 0 | BJ39: 0 | BK39: 1 | BL39: 300 | BM39: 0 | BN39: 0 | BO39: 0 | BP39: 0 | BQ39: 0 | BR39: 85685.8 | BS39: 682299 | BT39: =L39+U39+AB39+AE39+AN39+AQ39 -> 88700 | BU39: =AH39+AK39 -> 177768 | BV39: =AT39+AW39 -> 165166 | BW39: =+AZ39+BC39 -> 145920 | BX39: =BF39+BI39 -> 0 | BY39: =+BL39+BO39 -> 300 | BZ39: =M39+AC39+AF39+AI39+AL39+AO39+AR39+K39+AU39+AX39+BA39+BD39+BG39+BJ39+BM39+BP39 -> 104445 | CA39: =IF((BT39+BU39+BZ39+BV39+BW39+BX39+BY39)=BS39,BS39-BR39,"?""") -> 596613.2 | CB39: =ROUND(CA39*$CB$3,) -> 357968 | CD39: =CB39+CC39 -> 357968 | CE39: =A39 -> 룸비니 | CF39: =SUBSTITUTE(CE39," ","") -> 룸비니 | CG39: =CE39=CF39 -> TRUE | CH39: =CF39 -> 룸비니 | CI39: =IFERROR(_xlfn.XLOOKUP(CH39,$CF$5:$CF$60,$CD$5:$CD$60),"") -> 357968 | CJ39: MG | CK39: =SUMIFS('컨텐츠별 매출 통계'!CV:CV,'컨텐츠별 매출 통계'!A:A,'작품별 집계'!A39,'컨텐츠별 매출 통계'!CF:CF,"2026-01") -> 357968 | CL39: =CD39-CK39 -> 0
A40: 냉동무사 | B40: 609850 | D40: 더그림엔터테인먼트_브랜드 | E40: 최용준 | F40: 박만사 | G40: 15세 이상 이용가능 | H40: 2025.12.20 | I40: 0 | J40: 0 | K40: 0 | L40: 0 | M40: 0 | N40: 0 | O40: 0 | P40: 0 | Q40: 0 | R40: 0 | S40: 0 | T40: 0 | U40: 0 | V40: 0 | W40: 0 | X40: 0 | Y40: 0 | Z40: 0 | AA40: 687 | AB40: 89600 | AC40: 103600 | AD40: 4 | AE40: 0 | AF40: 1600 | AG40: 342 | AH40: 104019 | AI40: 15400 | AJ40: 2 | AK40: 960 | AL40: 0 | AM40: 118 | AN40: 34500 | AO40: 300 | AP40: 1 | AQ40: 400 | AR40: 0 | AS40: 321 | AT40: 113438 | AU40: 0 | AV40: 3 | AW40: 1440 | AX40: 0 | AY40: 524 | AZ40: 185880 | BA40: 0 | BB40: 1 | BC40: 480 | BD40: 0 | BE40: 5 | BF40: 1320 | BG40: 0 | BH40: 0 | BI40: 0 | BJ40: 0 | BK40: 5 | BL40: 1300 | BM40: 0 | BN40: 0 | BO40: 0 | BP40: 0 | BQ40: 0 | BR40: 63789.5 | BS40: 654237 | BT40: =L40+U40+AB40+AE40+AN40+AQ40 -> 124500 | BU40: =AH40+AK40 -> 104979 | BV40: =AT40+AW40 -> 114878 | BW40: =+AZ40+BC40 -> 186360 | BX40: =BF40+BI40 -> 1320 | BY40: =+BL40+BO40 -> 1300 | BZ40: =M40+AC40+AF40+AI40+AL40+AO40+AR40+K40+AU40+AX40+BA40+BD40+BG40+BJ40+BM40+BP40 -> 120900 | CA40: =IF((BT40+BU40+BZ40+BV40+BW40+BX40+BY40)=BS40,BS40-BR40,"?""") -> 590447.5 | CB40: =ROUND(CA40*$CB$3,) -> 354269 | CC40: -1 | CD40: =CB40+CC40 -> 354268 | CE40: =A40 -> 냉동무사 | CF40: =SUBSTITUTE(CE40," ","") -> 냉동무사 | CG40: =CE40=CF40 -> TRUE | CH40: =CF40 -> 냉동무사 | CI40: =IFERROR(_xlfn.XLOOKUP(CH40,$CF$5:$CF$60,$CD$5:$CD$60),"") -> 354268 | CJ40: MG | CK40: =SUMIFS('컨텐츠별 매출 통계'!CV:CV,'컨텐츠별 매출 통계'!A:A,'작품별 집계'!A40,'컨텐츠별 매출 통계'!CF:CF,"2026-01") -> 354268 | CL40: =CD40-CK40 -> 0
A41: 욕망일기Deep | B41: 534844 | D41: 더그림엔터테인먼트_브랜드 | E41: 박만사, 김꿀빨 | F41: 박만사 | G41: 15세 이상 이용가능 | H41: 2025.05.26 | I41: 0 | J41: 15367 | K41: 0 | L41: 0 | M41: 0 | N41: 0 | O41: 0 | P41: 0 | Q41: 0 | R41: 0 | S41: 0 | T41: 0 | U41: 0 | V41: 0 | W41: 0 | X41: 0 | Y41: 0 | Z41: 0 | AA41: 836 | AB41: 68000 | AC41: 95350 | AD41: 2 | AE41: 1500 | AF41: 0 | AG41: 495 | AH41: 103750 | AI41: 12600 | AJ41: 0 | AK41: 0 | AL41: 0 | AM41: 43 | AN41: 8600 | AO41: 0 | AP41: 0 | AQ41: 0 | AR41: 0 | AS41: 369 | AT41: 87816 | AU41: 200 | AV41: 0 | AW41: 0 | AX41: 0 | AY41: 108 | AZ41: 25920 | BA41: 0 | BB41: 0 | BC41: 0 | BD41: 0 | BE41: 0 | BF41: 0 | BG41: 0 | BH41: 0 | BI41: 0 | BJ41: 0 | BK41: 33 | BL41: 6500 | BM41: 0 | BN41: 0 | BO41: 0 | BP41: 0 | BQ41: 0 | BR41: 45557.4 | BS41: 410236 | BT41: =L41+U41+AB41+AE41+AN41+AQ41 -> 78100 | BU41: =AH41+AK41 -> 103750 | BV41: =AT41+AW41 -> 87816 | BW41: =+AZ41+BC41 -> 25920 | BX41: =BF41+BI41 -> 0 | BY41: =+BL41+BO41 -> 6500 | BZ41: =M41+AC41+AF41+AI41+AL41+AO41+AR41+K41+AU41+AX41+BA41+BD41+BG41+BJ41+BM41+BP41 -> 108150 | CA41: =IF((BT41+BU41+BZ41+BV41+BW41+BX41+BY41)=BS41,BS41-BR41,"?""") -> 364678.6 | CB41: =ROUND(CA41*$CB$3,) -> 218807 | CD41: =CB41+CC41 -> 218807 | CE41: =A41 -> 욕망일기Deep | CF41: =SUBSTITUTE(CE41," ","") -> 욕망일기Deep | CG41: =CE41=CF41 -> TRUE | CH41: =CF41 -> 욕망일기Deep | CI41: =IFERROR(_xlfn.XLOOKUP(CH41,$CF$5:$CF$60,$CD$5:$CD$60),"") -> 218807 | CJ41: MG | CK41: =SUMIFS('컨텐츠별 매출 통계'!CV:CV,'컨텐츠별 매출 통계'!A:A,'작품별 집계'!A41,'컨텐츠별 매출 통계'!CF:CF,"2026-01") -> 218807 | CL41: =CD41-CK41 -> 0
...

Sheet 컨텐츠별 매출 통계
A1: 네이버 프렌즈 어드민 > Comic > [시리즈] 매출 통계(이용권 포함) > [CP용] 컨텐츠별 매출 통계
